Workbook

Sheet Daily
A1: DAILY CONTAINER STOCK | AK1: DATE: | AL1: 29/10/2026
A2: LOCATION | C2: FULL INBOUND (BKK) | L2: CURRENT STOCK | R2: =AL1 -> 29/10/2026 | V2: LOCATION | X2: FULL INBOUND (LCH) | AG2: CURRENT STOCK | AM2: =R2 -> 29/10/2026
C3: 22GP | D3: 42GP | E3: 45GP | F3: 22RE | G3: 45RE | H3: 22UT | I3: 42UT | J3: 22PC | K3: 42PC | L3: 22GP | M3: 42GP | N3: 45GP | O3: 22RE | P3: 45RE | Q3: 22UT | R3: 42UT | S3: 22PC | T3: 42PC | X3: 22GP | Y3: 42GP | Z3: 45GP | AA3: 22RE | AB3: 45RE | AC3: 22UT | AD3: 42UT | AE3: 22PC | AF3: 42PC | AG3: 22GP | AH3: 42GP | AI3: 45GP | AJ3: 22RE | AK3: 45RE | AL3: 22UT | AM3: 42UT | AN3: 22PC | AO3: 42PC
A4: PAT | B4: TERMINAL | C4: 209 | E4: 136 | F4: 2 | G4: 12 | L4: 90 | N4: 42 | V4: LCMT | W4: TERMINAL | X4: 95 | Z4: 89 | AA4: 1 | AB4: 7 | AD4: 1 | AF4: 2
A5: UNITHAI | B5: TERMINAL | C5: 27 | E5: 18 | L5: 189 | N5: 45 | V5: HUTCHISON | W5: TERMINAL | X5: 105 | Z5: 76
W6: TERMINAL
A7: YJC II | B7: DEPOT | L7: 52 | N7: 61 | V7: ESCO | W7: TERMINAL | X7: 11 | Z7: 25 | AF7: 2
A8: CDS | B8: DEPOT | L8: 1202 | N8: 632 | O8: 29 | P8: 26 | R8: 2 | T8: 1 | V8: LCIT | W8: TERMINAL | X8: 1 | Z8: 4
A9: TIFFA | B9: ICD | C9: 52 | E9: 7 | N9: 1 | V9: YJC | W9: DEPOT | AG9: 1272 | AH9: 2 | AI9: 734 | AJ9: 4 | AK9: 44 | AM9: 6 | AN9: 1 | AO9: 7
V10: CDS LCH | W10: DEPOT | AG10: 167 | AI10: 177
A11: ESCO | B11: ICD | G11: 1 | L11: 15 | N11: 6 | V11: PH | W11: DEPOT | AG11: 337 | AI11: 317 | AJ11: 1
V12: JWD | W12: ICD | X12: 3 | Z12: 1
A13: LEASE IN | V13: LEASE IN
A14: REPO (E/P) | V14: REPO (E/P) | AG14: 297 | AI14: 20
A15: TOTAL AT BKK | C15: =SUM(C4:C14) -> 288 | D15: =SUM(D4:D14) -> 0 | E15: =SUM(E4:E14) -> 161 | F15: =SUM(F4:F14) -> 2 | G15: =SUM(G4:G14) -> 13 | H15: =SUM(H4:H14) -> 0 | I15: =SUM(I4:I14) -> 0 | J15: =SUM(J4:J14) -> 0 | ... T15: =SUM(T4:T14) -> 1 | V15: TOTAL AT LCH | X15: =SUM(X4:X14) -> 215 | Y15: =SUM(Y4:Y14) -> 0 | Z15: =SUM(Z4:Z14) -> 195 | AA15: =SUM(AA4:AA14) -> 1 | AB15: =SUM(AB4:AB14) -> 7 | AC15: =SUM(AC4:AC14) -> 0 | AD15: =SUM(AD4:AD14) -> 1 | AE15: =SUM(AE4:AE14) -> 0 | ... AO15: =SUM(AO4:AO14) -> 7
A17: LOCATION | L17: STOCK END WK | V17: LOCATION | AG17: STOCK END WK
L18: 22GP | M18: 42GP | N18: 45GP | O18: 22RE | P18: 45RE | Q18: 22UT | R18: 42UT | S18: 22PC | T18: 42PC | AG18: 22GP | AH18: 42GP | AI18: 45GP | AJ18: 22RE | AK18: 45RE | AL18: 22UT | AM18: 42UT | AN18: 22PC | AO18: 42PC
A19: REPO IN（E/P） | V19: REPO IN（E/P）
A20: LEASE IN | V20: LEASE IN
A24: TOTAL AT BKK | V24: TOTAL AT BKK
A29: LOCATION | C29: BOOKING W 1 | I29: 29-01/11/2026 | L29: STOCK END WK | V29: LOCATION | X29: =C29 -> BOOKING W 1 | AD29: =I29 -> 29-01/11/2026 | AG29: STOCK END WK
C30: 22GP | D30: 42GP | E30: 45GP | F30: 22RE | G30: 45RE | H30: 22UT | I30: 42UT | J30: 22PC | K30: 42PC | L30: 22GP | M30: 42GP | N30: 45GP | O30: 22RE | P30: 45RE | Q30: 22UT | R30: 42UT | S30: 22PC | T30: 42PC | X30: 22GP | Y30: 42GP | Z30: 45GP | AA30: 22RE | AB30: 45RE | AC30: 22UT | AD30: 42UT | AE30: 22PC | AF30: 42PC | AG30: 22GP | AH30: 42GP | AI30: 45GP | AJ30: 22RE | AK30: 45RE | AL30: 22UT | AM30: 42UT | AN30: 22PC | AO30: 42PC
A31: PAT | B31: TERMINAL | C31: 18 | E31: 19 | L31: =SUM(L4-C31) -> 72 | M31: =SUM(M4-D31) -> 0 | N31: =SUM(N4-E31) -> 23 | O31: =SUM(O4-F31) -> 0 | P31: =SUM(P4-G31) -> 0 | Q31: =SUM(Q4-H31) -> 0 | R31: =SUM(R4-I31) -> 0 | S31: =SUM(S4-J31) -> 0 | T31: =SUM(T4-K31) -> 0 | V31: LCMT | W31: TERMINAL | AG31: =SUM(AG4-X31) -> 0 | AH31: =SUM(AH4-Y31) -> 0 | AI31: =SUM(AI4-Z31) -> 0 | AJ31: =SUM(AJ4-AA31) -> 0 | AK31: =SUM(AK4-AB31) -> 0 | AL31: =SUM(AL4-AC31) -> 0 | AM31: =SUM(AM4-AD31) -> 0 | AN31: =SUM(AN4-AE31) -> 0 | AO31: =SUM(AO4-AF31) -> 0
A32: UNITHAI | B32: TERMINAL | C32: 12 | E32: 10 | L32: =SUM(L5-C32) -> 177 | M32: =SUM(M5-D32) -> 0 | N32: =SUM(N5-E32) -> 35 | O32: =SUM(O5-F32) -> 0 | P32: =SUM(P5-G32) -> 0 | Q32: =SUM(Q5-H32) -> 0 | R32: =SUM(R5-I32) -> 0 | S32: =SUM(S5-J32) -> 0 | T32: =SUM(T5-K32) -> 0 | V32: LCHZZ | W32: TERMINAL | AG32: =SUM(AG5-X32) -> 0 | AH32: =SUM(AH5-Y32) -> 0 | AI32: =SUM(AI5-Z32) -> 0 | AJ32: =SUM(AJ5-AA32) -> 0 | AK32: =SUM(AK5-AB32) -> 0 | AL32: =SUM(AL5-AC32) -> 0 | AM32: =SUM(AM5-AD32) -> 0 | AN32: =SUM(AN5-AE32) -> 0 | AO32: =SUM(AO5-AF32) -> 0
N33: =SUM(N6-E33) -> 0 | O33: =SUM(O6-F33) -> 0 | P33: =SUM(P6-G33) -> 0 | Q33: =SUM(Q6-H33) -> 0 | R33: =SUM(R6-I33) -> 0 | S33: =SUM(S6-J33) -> 0 | T33: =SUM(T6-K33) -> 0 | V33: TIPS | W33: TERMINAL | AG33: =SUM(AG6-X33) -> 0 | AH33: =SUM(AH6-Y33) -> 0 | AI33: =SUM(AI6-Z33) -> 0 | AJ33: =SUM(AJ6-AA33) -> 0 | AK33: =SUM(AK6-AB33) -> 0 | AL33: =SUM(AL6-AC33) -> 0 | AM33: =SUM(AM6-AD33) -> 0 | AN33: =SUM(AN6-AE33) -> 0 | AO33: =SUM(AO6-AF33) -> 0
A34: YJC II | B34: DEPOT | C34: 18 | E34: 24 | L34: =SUM(L7-C34) -> 34 | M34: =SUM(M7-D34) -> 0 | N34: =SUM(N7-E34) -> 37 | O34: =SUM(O7-F34) -> 0 | P34: =SUM(P7-G34) -> 0 | Q34: =SUM(Q7-H34) -> 0 | R34: =SUM(R7-I34) -> 0 | S34: =SUM(S7-J34) -> 0 | T34: =SUM(T7-K34) -> 0 | V34: ESCO | W34: TERMINAL | AG34: =SUM(AG7-X34) -> 0 | AH34: =SUM(AH7-Y34) -> 0 | AI34: =SUM(AI7-Z34) -> 0 | AJ34: =SUM(AJ7-AA34) -> 0 | AK34: =SUM(AK7-AB34) -> 0 | AL34: =SUM(AL7-AC34) -> 0 | AM34: =SUM(AM7-AD34) -> 0 | AN34: =SUM(AN7-AE34) -> 0 | AO34: =SUM(AO7-AF34) -> 0
A35: CDS | B35: DEPOT | C35: 158 | E35: 94 | F35: 6 | G35: 19 | L35: =SUM(L8-C35) -> 1044 | M35: =SUM(M8-D35) -> 0 | N35: =SUM(N8-E35) -> 538 | O35: =SUM(O8-F35) -> 23 | P35: =SUM(P8-G35) -> 7 | Q35: =SUM(Q8-H35) -> 0 | R35: =SUM(R8-I35) -> 2 | S35: =SUM(S8-J35) -> 0 | T35: =SUM(T8-K35) -> 1 | V35: LCIT | W35: TERMINAL | AG35: =SUM(AG8-X35) -> 0 | AH35: =SUM(AH8-Y35) -> 0 | AI35: =SUM(AI8-Z35) -> 0 | AJ35: =SUM(AJ8-AA35) -> 0 | AK35: =SUM(AK8-AB35) -> 0 | AL35: =SUM(AL8-AC35) -> 0 | AM35: =SUM(AM8-AD35) -> 0 | AN35: =SUM(AN8-AE35) -> 0 | AO35: =SUM(AO8-AF35) -> 0
A36: TIFFA | B36: ICD | L36: =SUM(L9-C36) -> 0 | M36: =SUM(M9-D36) -> 0 | N36: =SUM(N9-E36) -> 1 | O36: =SUM(O9-F36) -> 0 | P36: =SUM(P9-G36) -> 0 | Q36: =SUM(Q9-H36) -> 0 | R36: =SUM(R9-I36) -> 0 | S36: =SUM(S9-J36) -> 0 | T36: =SUM(T9-K36) -> 0 | V36: YJC | W36: DEPOT | X36: 90 | Z36: 80 | AB36: 23 | AG36: =SUM(AG9-X36) -> 1182 | AH36: =SUM(AH9-Y36) -> 2 | AI36: =SUM(AI9-Z36) -> 654 | AJ36: =SUM(AJ9-AA36) -> 4 | AK36: =SUM(AK9-AB36) -> 21 | AL36: =SUM(AL9-AC36) -> 0 | AM36: =SUM(AM9-AD36) -> 6 | AN36: =SUM(AN9-AE36) -> 1 | AO36: =SUM(AO9-AF36) -> 7
L37: =SUM(L10-C37) -> 0 | M37: =SUM(M10-D37) -> 0 | N37: =SUM(N10-E37) -> 0 | O37: =SUM(O10-F37) -> 0 | P37: =SUM(P10-G37) -> 0 | Q37: =SUM(Q10-H37) -> 0 | R37: =SUM(R10-I37) -> 0 | S37: =SUM(S10-J37) -> 0 | T37: =SUM(T10-K37) -> 0 | V37: CDS LCH | W37: DEPOT | X37: 13 | Z37: 9 | AG37: =SUM(AG10-X37) -> 154 | AH37: =SUM(AH10-Y37) -> 0 | AI37: =SUM(AI10-Z37) -> 168 | AJ37: =SUM(AJ10-AA37) -> 0 | AK37: =SUM(AK10-AB37) -> 0 | AL37: =SUM(AL10-AC37) -> 0 | AM37: =SUM(AM10-AD37) -> 0 | AN37: =SUM(AN10-AE37) -> 0 | AO37: =SUM(AO10-AF37) -> 0
A38: ESCO | B38: ICD | L38: =SUM(L11-C38) -> 15 | M38: =SUM(M11-D38) -> 0 | N38: =SUM(N11-E38) -> 6 | O38: =SUM(O11-F38) -> 0 | P38: =SUM(P11-G38) -> 0 | Q38: =SUM(Q11-H38) -> 0 | R38: =SUM(R11-I38) -> 0 | S38: =SUM(S11-J38) -> 0 | T38: =SUM(T11-K38) -> 0 | V38: PH | W38: DEPOT | X38: 7 | Z38: 42 | AG38: =SUM(AG11-X38) -> 330 | AH38: =SUM(AH11-Y38) -> 0 | AI38: =SUM(AI11-Z38) -> 275 | AJ38: =SUM(AJ11-AA38) -> 1 | AK38: =SUM(AK11-AB38) -> 0 | AL38: =SUM(AL11-AC38) -> 0 | AM38: =SUM(AM11-AD38) -> 0 | AN38: =SUM(AN11-AE38) -> 0 | AO38: =SUM(AO11-AF38) -> 0
V39: JWD | W39: ICD | AG39: =SUM(AG12-X39) -> 0 | AH39: =SUM(AH12-Y39) -> 0 | AI39: =SUM(AI12-Z39) -> 0 | AJ39: =SUM(AJ12-AA39) -> 0 | AK39: =SUM(AK12-AB39) -> 0 | AL39: =SUM(AL12-AC39) -> 0 | AM39: =SUM(AM12-AD39) -> 0 | AN39: =SUM(AN12-AE39) -> 0 | AO39: =SUM(AO12-AF39) -> 0
A40: LEASE IN | L40: =SUM(L13-C40) -> 0 | M40: =SUM(M13-D40) -> 0 | N40: =SUM(N13-E40) -> 0 | O40: =SUM(O13-F40) -> 0 | P40: =SUM(P13-G40) -> 0 | Q40: =SUM(Q13-H40) -> 0 | R40: =SUM(R13-I40) -> 0 | S40: =SUM(S13-J40) -> 0 | T40: =SUM(T13-K40) -> 0 | V40: LEASE IN | AG40: =SUM(AG13-X40) -> 0 | AH40: =SUM(AH13-Y40) -> 0 | AI40: =SUM(AI13-Z40) -> 0 | AJ40: =SUM(AJ13-AA40) -> 0 | AK40: =SUM(AK13-AB40) -> 0 | AL40: =SUM(AL13-AC40) -> 0 | AM40: =SUM(AM13-AD40) -> 0 | AN40: =SUM(AN13-AE40) -> 0 | AO40: =SUM(AO13-AF40) -> 0
A41: TOTAL AT BKK | C41: =SUM(C31:C40) -> 206 | D41: =SUM(D31:D40) -> 0 | E41: =SUM(E31:E40) -> 147 | F41: =SUM(F31:F40) -> 6 | G41: =SUM(G31:G40) -> 19 | H41: =SUM(H31:H40) -> 0 | I41: =SUM(I31:I40) -> 0 | J41: =SUM(J31:J40) -> 0 | ... T41: =SUM(T31:T40) -> 1 | V41: TOTAL AT LCH | X41: =SUM(X31:X40) -> 110 | Y41: =SUM(Y31:Y40) -> 0 | Z41: =SUM(Z31:Z40) -> 131 | AA41: =SUM(AA31:AA40) -> 0 | AB41: =SUM(AB31:AB40) -> 23 | AC41: =SUM(AC31:AC40) -> 0 | AD41: =SUM(AD31:AD40) -> 0 | AE41: =SUM(AE31:AE40) -> 0 | ... AO41: =SUM(AO31:AO40) -> 7
A43: LOCATION | C43: BOOKING W 2 | I43: 02-08/11/2026 | L43: STOCK END WK | V43: LOCATION | X43: =C43 -> BOOKING W 2 | AD43: =I43 -> 02-08/11/2026 | AG43: STOCK END WK
C44: 22GP | D44: 42GP | E44: 45GP | F44: 22RE | G44: 45RE | H44: 22UT | I44: 42UT | J44: 22PC | K44: 42PC | L44: 22GP | M44: 42GP | N44: 45GP | O44: 22RE | P44: 45RE | Q44: 22UT | R44: 42UT | S44: 22PC | T44: 42PC | X44: 22GP | Y44: 42GP | Z44: 45GP | AA44: 22RE | AB44: 45RE | AC44: 22UT | AD44: 42UT | AE44: 22PC | AF44: 42PC | AG44: 22GP | AH44: 42GP | AI44: 45GP | AJ44: 22RE | AK44: 45RE | AL44: 22UT | AM44: 42UT | AN44: 22PC | AO44: 42PC
A45: PAT | B45: TERMINAL | C45: 35 | E45: 40 | L45: =SUM(L31-C45) -> 37 | M45: =SUM(M31-D45) -> 0 | N45: =SUM(N31-E45) -> -17 | O45: =SUM(O31-F45) -> 0 | P45: =SUM(P31-G45) -> 0 | Q45: =SUM(Q31-H45) -> 0 | R45: =SUM(R31-I45) -> 0 | S45: =SUM(S31-J45) -> 0 | T45: =SUM(T31-K45) -> 0 | V45: LCMT | W45: TERMINAL | AG45: =SUM(AG31-X45) -> 0 | AH45: =SUM(AH31-Y45) -> 0 | AI45: =SUM(AI31-Z45) -> 0 | AJ45: =SUM(AJ31-AA45) -> 0 | AK45: =SUM(AK31-AB45) -> 0 | AL45: =SUM(AL31-AC45) -> 0 | AM45: =SUM(AM31-AD45) -> 0 | AN45: =SUM(AN31-AE45) -> 0 | AO45: =SUM(AO31-AF45) -> 0
A46: UNITHAI | B46: TERMINAL | C46: 67 | E46: 16 | L46: =SUM(L32-C46) -> 110 | M46: =SUM(M32-D46) -> 0 | N46: =SUM(N32-E46) -> 19 | O46: =SUM(O32-F46) -> 0 | P46: =SUM(P32-G46) -> 0 | Q46: =SUM(Q32-H46) -> 0 | R46: =SUM(R32-I46) -> 0 | S46: =SUM(S32-J46) -> 0 | T46: =SUM(T32-K46) -> 0 | V46: LCHZZ | W46: TERMINAL | AG46: =SUM(AG32-X46) -> 0 | AH46: =SUM(AH32-Y46) -> 0 | AI46: =SUM(AI32-Z46) -> 0 | AJ46: =SUM(AJ32-AA46) -> 0 | AK46: =SUM(AK32-AB46) -> 0 | AL46: =SUM(AL32-AC46) -> 0 | AM46: =SUM(AM32-AD46) -> 0 | AN46: =SUM(AN32-AE46) -> 0 | AO46: =SUM(AO32-AF46) -> 0
Q47: =SUM(Q33-H47) -> 0 | R47: =SUM(R33-I47) -> 0 | S47: =SUM(S33-J47) -> 0 | T47: =SUM(T33-K47) -> 0 | V47: TIPS | W47: TERMINAL | AG47: =SUM(AG33-X47) -> 0 | AH47: =SUM(AH33-Y47) -> 0 | AI47: =SUM(AI33-Z47) -> 0 | AJ47: =SUM(AJ33-AA47) -> 0 | AK47: =SUM(AK33-AB47) -> 0 | AL47: =SUM(AL33-AC47) -> 0 | AM47: =SUM(AM33-AD47) -> 0 | AN47: =SUM(AN33-AE47) -> 0 | AO47: =SUM(AO33-AF47) -> 0
A48: YJC II | B48: DEPOT | C48: 55 | E48: 28 | L48: =SUM(L34-C48) -> -21 | M48: =SUM(M34-D48) -> 0 | N48: =SUM(N34-E48) -> 9 | O48: =SUM(O34-F48) -> 0 | P48: =SUM(P34-G48) -> 0 | Q48: =SUM(Q34-H48) -> 0 | R48: =SUM(R34-I48) -> 0 | S48: =SUM(S34-J48) -> 0 | T48: =SUM(T34-K48) -> 0 | V48: ESCO | W48: TERMINAL | AG48: =SUM(AG34-X48) -> 0 | AH48: =SUM(AH34-Y48) -> 0 | AI48: =SUM(AI34-Z48) -> 0 | AJ48: =SUM(AJ34-AA48) -> 0 | AK48: =SUM(AK34-AB48) -> 0 | AL48: =SUM(AL34-AC48) -> 0 | AM48: =SUM(AM34-AD48) -> 0 | AN48: =SUM(AN34-AE48) -> 0 | AO48: =SUM(AO34-AF48) -> 0
A49: CDS | B49: DEPOT | C49: 353 | D49: 1 | E49: 180 | F49: 5 | G49: 10 | L49: =SUM(L35-C49) -> 691 | M49: =SUM(M35-D49) -> -1 | N49: =SUM(N35-E49) -> 358 | O49: =SUM(O35-F49) -> 18 | P49: =SUM(P35-G49) -> -3 | Q49: =SUM(Q35-H49) -> 0 | R49: =SUM(R35-I49) -> 2 | S49: =SUM(S35-J49) -> 0 | T49: =SUM(T35-K49) -> 1 | V49: LCIT | W49: TERMINAL | AG49: =SUM(AG35-X49) -> 0 | AH49: =SUM(AH35-Y49) -> 0 | AI49: =SUM(AI35-Z49) -> 0 | AJ49: =SUM(AJ35-AA49) -> 0 | AK49: =SUM(AK35-AB49) -> 0 | AL49: =SUM(AL35-AC49) -> 0 | AM49: =SUM(AM35-AD49) -> 0 | AN49: =SUM(AN35-AE49) -> 0 | AO49: =SUM(AO35-AF49) -> 0
...

Sheet New Format
A1: SKR-THBKK
A2: Item | B2: 22GP | C2: 42GP | D2: 45GP | E2: 22RE | F2: 45RE | G2: 22UT | H2: 42UT | I2: 22PC | J2: 42PC | L2: BKK | Q2: LCH
A3: Current Stock | B3: =Daily!L15 -> 1548 | C3: =Daily!M15 -> 0 | D3: =Daily!N15 -> 787 | E3: =Daily!O15 -> 29 | F3: =Daily!P15 -> 26 | G3: =Daily!Q15 -> 0 | H3: =Daily!R15 -> 2 | I3: =Daily!S15 -> 0 | J3: =Daily!T15 -> 1 | L3: YEAR BUILT | M3: CARRIER | N3: DAIKIN | O3: THERMOKING | Q3: YEAR BUILT | R3: CARRIER | S3: DAIKIN | T3: THERMOKING
A4: E/P In (this week) | M4: 45RE | N4: 45RE | O4: 45RE | R4: 45RE | S4: 45RE | T4: 45RE
A5: E/P In (next week) | L5: 2025 | M5: 11 | N5: 0 | O5: 3 | Q5: 2025 | R5: 24 | S5: 0 | T5: 0
A6: Lease In HAL | L6: 2023 | M6: 1 | N6: 0 | O6: 0 | Q6: 2023 | R6: 4 | S6: 0 | T6: 0
A7: IED(Estimated) | B7: =Daily!C15 -> 288 | C7: =Daily!D15 -> 0 | D7: =Daily!E15 -> 161 | E7: =Daily!F15 -> 2 | F7: =Daily!G15 -> 13 | G7: =Daily!H15 -> 0 | H7: =Daily!I15 -> 0 | I7: =Daily!J15 -> 0 | J7: =Daily!K15 -> 0 | L7: 2021 | M7: 3 | N7: 0 | O7: 0 | Q7: 2021 | R7: 5 | S7: 0 | T7: 0
A8: Booking (29-01/11)2026 | B8: =Daily!C41 -> 206 | C8: =Daily!D41 -> 0 | D8: =Daily!E41 -> 147 | E8: =Daily!F41 -> 6 | F8: =Daily!G41 -> 19 | G8: =Daily!H41 -> 0 | H8: =Daily!I41 -> 0 | I8: =Daily!J41 -> 0 | J8: =Daily!K41 -> 0 | L8: 2020 | M8: 3 | N8: 0 | O8: 0 | Q8: 2020 | R8: 3 | S8: 0 | T8: 0
A9: Booking (02-08/11)2026 | B9: =Daily!C55 -> 510 | C9: =Daily!D55 -> 1 | D9: =Daily!E55 -> 264 | E9: =Daily!F55 -> 5 | F9: =Daily!G55 -> 10 | G9: =Daily!H55 -> 0 | H9: =Daily!I55 -> 0 | I9: =Daily!J55 -> 0 | J9: =Daily!K55 -> 0 | L9: TOTAL | M9: =SUM(M5:M8) -> 18 | N9: =SUM(N5:N8) -> 0 | O9: =SUM(O5:O8) -> 3 | Q9: TOTAL | R9: =SUM(R5:R8) -> 36 | S9: =SUM(S5:S8) -> 0 | T9: =SUM(T5:T8) -> 0
A10: Balance | B10: =(B3+B4+B5+B6+B7)-(B8+B9) -> 1120 | C10: =(C3+C4+C5+C6+C7)-(C8+C9) -> -1 | D10: =(D3+D4+D5+D6+D7)-(D8+D9) -> 537 | E10: =(E3+E4+E5+E6+E7)-(E8+E9) -> 20 | F10: =(F3+F4+F5+F6+F7)-(F8+F9) -> 10 | G10: =(G3+G4+G5+G6+G7)-(G8+G9) -> 0 | H10: =(H3+H4+H5+H6+H7)-(H8+H9) -> 2 | I10: =(I3+I4+I5+I6+I7)-(I8+I9) -> 0 | J10: =(J3+J4+J5+J6+J7)-(J8+J9) -> 1
A13: SKR-THLCH
A14: Item | B14: 22GP | C14: 42GP | D14: 45GP | E14: 22RE | F14: 45RE | G14: 22UT | H14: 42UT | I14: 22PC | J14: 42PC
A15: Current Stock | B15: =Daily!AG15 -> 2073 | C15: =Daily!AH15 -> 2 | D15: =Daily!AI15 -> 1248 | E15: =Daily!AJ15 -> 5 | F15: =Daily!AK15 -> 44 | G15: =Daily!AL15 -> 0 | H15: =Daily!AM15 -> 6 | I15: =Daily!AN15 -> 1 | J15: =Daily!AO15 -> 7
A16: E/P In (this week)
A17: E/P In (next week)
A18: Lease In HAL
A19: IED(Estimated) | B19: =Daily!X15 -> 215 | C19: =Daily!Y15 -> 0 | D19: =Daily!Z15 -> 195 | E19: =Daily!AA15 -> 1 | F19: =Daily!AB15 -> 7 | G19: =Daily!AC15 -> 0 | H19: =Daily!AD15 -> 1 | I19: =Daily!AE15 -> 0 | J19: =Daily!AF15 -> 4
A20: =A8 -> Booking (29-01/11)2026 | B20: =Daily!X41 -> 110 | C20: =Daily!Y41 -> 0 | D20: =Daily!Z41 -> 131 | E20: =Daily!AA41 -> 0 | F20: =Daily!AB41 -> 23 | G20: =Daily!AC41 -> 0 | H20: =Daily!AD41 -> 0 | I20: =Daily!AE41 -> 0 | J20: =Daily!AF41 -> 0
A21: =A9 -> Booking (02-08/11)2026 | B21: =Daily!X55 -> 369 | C21: =Daily!Y55 -> 0 | D21: =Daily!Z55 -> 188 | E21: =Daily!AA55 -> 5 | F21: =Daily!AB55 -> 12 | G21: =Daily!AC55 -> 0 | H21: =Daily!AD55 -> 0 | I21: =Daily!AE55 -> 0 | J21: =Daily!AF55 -> 0
A22: Balance | B22: =(B15+B16+B17+B18+B19)-(B20+B21) -> 1809 | C22: =(C15+C16+C17+C18+C19)-(C20+C21) -> 2 | D22: =(D15+D16+D17+D18+D19)-(D20+D21) -> 1124 | E22: =(E15+E16+E17+E18+E19)-(E20+E21) -> 1 | F22: =(F15+F16+F17+F18+F19)-(F20+F21) -> 16 | G22: =(G15+G16+G17+G18+G19)-(G20+G21) -> 0 | H22: =(H15+H16+H17+H18+H19)-(H20+H21) -> 7 | I22: =(I15+I16+I17+I18+I19)-(I20+I21) -> 1 | J22: =(J15+J16+J17+J18+J19)-(J20+J21) -> 11
