Workbook

Sheet Terminal Summary
A1: Berth Waiting Time Analysis — ETA to ETB
A2: Terminals covered: THBKK (Bangkok) and THLCH (Laem Chabang) | Source: uploaded vessel schedule (Jan–Sep 2026)
A4: Terminal Comparison — Waiting Time (ETA → ETB)
A5: Terminal | B5: Calls (Count) | C5: Avg Wait (Hrs) | D5: Median Wait (Hrs) | E5: Min Wait (Hrs) | F5: Max Wait (Hrs) | G5: Total Wait (Hrs) | H5: Std Dev (Hrs) | I5: 90th Percentile (Hrs)
A6: THBKK | B6: =COUNTIF('Raw Data'!$J$2:$J$670,$A6) -> 209 | C6: =AVERAGEIF('Raw Data'!$J$2:$J$670,$A6,'Raw Data'!$S$2:$S$670) -> 11.209411 | D6: {=MEDIAN(IF('Raw Data'!$J$2:$J$670=$A6,'Raw Data'!$S$2:$S$670))} -> 8.5 | E6: =_xlfn.MINIFS('Raw Data'!$S$2:$S$670,'Raw Data'!$J$2:$J$670,$A6) -> 0.0167 | F6: =_xlfn.MAXIFS('Raw Data'!$S$2:$S$670,'Raw Data'!$J$2:$J$670,$A6) -> 58 | G6: =SUMIF('Raw Data'!$J$2:$J$670,$A6,'Raw Data'!$S$2:$S$670) -> 2342.767 | H6: {=STDEV(IF('Raw Data'!$J$2:$J$670=$A6,'Raw Data'!$S$2:$S$670))} -> 11.420177 | I6: {=PERCENTILE(IF('Raw Data'!$J$2:$J$670=$A6,'Raw Data'!$S$2:$S$670),0.9)} -> 24.68
A7: THLCH | B7: =COUNTIF('Raw Data'!$J$2:$J$670,$A7) -> 460 | C7: =AVERAGEIF('Raw Data'!$J$2:$J$670,$A7,'Raw Data'!$S$2:$S$670) -> 3.9727189 | D7: {=MEDIAN(IF('Raw Data'!$J$2:$J$670=$A7,'Raw Data'!$S$2:$S$670))} -> 1 | E7: =_xlfn.MINIFS('Raw Data'!$S$2:$S$670,'Raw Data'!$J$2:$J$670,$A7) -> 0 | F7: =_xlfn.MAXIFS('Raw Data'!$S$2:$S$670,'Raw Data'!$J$2:$J$670,$A7) -> 72 | G7: =SUMIF('Raw Data'!$J$2:$J$670,$A7,'Raw Data'!$S$2:$S$670) -> 1827.4507 | H7: {=STDEV(IF('Raw Data'!$J$2:$J$670=$A7,'Raw Data'!$S$2:$S$670))} -> 7.1799504 | I7: {=PERCENTILE(IF('Raw Data'!$J$2:$J$670=$A7,'Raw Data'!$S$2:$S$670),0.9)} -> 10.82
A9: Finding: THBKK shows ~3x longer average berth waiting time than THLCH over the period. See HTML/summary notes.
A11: Wharf / Berth Breakdown
A12: Terminal | B12: Wharf | C12: Calls (Count) | D12: Avg Wait (Hrs) | E12: Max Wait (Hrs)
A13: THBKK | B13: BKK01 | C13: =COUNTIFS('Raw Data'!$J$2:$J$670,$A13,'Raw Data'!$I$2:$I$670,$B13) -> 91 | D13: =_xlfn.IFS(C13=0,0,C13>0,AVERAGEIFS('Raw Data'!$S$2:$S$670,'Raw Data'!$J$2:$J$670,$A13,'Raw Data'!$I$2:$I$670,$B13)) -> 15.055676 | E13: =_xlfn.MAXIFS('Raw Data'!$S$2:$S$670,'Raw Data'!$J$2:$J$670,$A13,'Raw Data'!$I$2:$I$670,$B13) -> 58
A14: THBKK | B14: BKK02 | C14: =COUNTIFS('Raw Data'!$J$2:$J$670,$A14,'Raw Data'!$I$2:$I$670,$B14) -> 64 | D14: =_xlfn.IFS(C14=0,0,C14>0,AVERAGEIFS('Raw Data'!$S$2:$S$670,'Raw Data'!$J$2:$J$670,$A14,'Raw Data'!$I$2:$I$670,$B14)) -> 4.0906328 | E14: =_xlfn.MAXIFS('Raw Data'!$S$2:$S$670,'Raw Data'!$J$2:$J$670,$A14,'Raw Data'!$I$2:$I$670,$B14) -> 20.5
A15: THBKK | B15: BKK04 | C15: =COUNTIFS('Raw Data'!$J$2:$J$670,$A15,'Raw Data'!$I$2:$I$670,$B15) -> 54 | D15: =_xlfn.IFS(C15=0,0,C15>0,AVERAGEIFS('Raw Data'!$S$2:$S$670,'Raw Data'!$J$2:$J$670,$A15,'Raw Data'!$I$2:$I$670,$B15)) -> 13.164815 | E15: =_xlfn.MAXIFS('Raw Data'!$S$2:$S$670,'Raw Data'!$J$2:$J$670,$A15,'Raw Data'!$I$2:$I$670,$B15) -> 45
A16: THLCH | B16: LCH01 | C16: =COUNTIFS('Raw Data'!$J$2:$J$670,$A16,'Raw Data'!$I$2:$I$670,$B16) -> 76 | D16: =_xlfn.IFS(C16=0,0,C16>0,AVERAGEIFS('Raw Data'!$S$2:$S$670,'Raw Data'!$J$2:$J$670,$A16,'Raw Data'!$I$2:$I$670,$B16)) -> 4.5291671 | E16: =_xlfn.MAXIFS('Raw Data'!$S$2:$S$670,'Raw Data'!$J$2:$J$670,$A16,'Raw Data'!$I$2:$I$670,$B16) -> 40
A17: THLCH | B17: LCH02 | C17: =COUNTIFS('Raw Data'!$J$2:$J$670,$A17,'Raw Data'!$I$2:$I$670,$B17) -> 22 | D17: =_xlfn.IFS(C17=0,0,C17>0,AVERAGEIFS('Raw Data'!$S$2:$S$670,'Raw Data'!$J$2:$J$670,$A17,'Raw Data'!$I$2:$I$670,$B17)) -> 2.1901591 | E17: =_xlfn.MAXIFS('Raw Data'!$S$2:$S$670,'Raw Data'!$J$2:$J$670,$A17,'Raw Data'!$I$2:$I$670,$B17) -> 25
A18: THLCH | B18: LCH03 | C18: =COUNTIFS('Raw Data'!$J$2:$J$670,$A18,'Raw Data'!$I$2:$I$670,$B18) -> 5 | D18: =_xlfn.IFS(C18=0,0,C18>0,AVERAGEIFS('Raw Data'!$S$2:$S$670,'Raw Data'!$J$2:$J$670,$A18,'Raw Data'!$I$2:$I$670,$B18)) -> 3.5 | E18: =_xlfn.MAXIFS('Raw Data'!$S$2:$S$670,'Raw Data'!$J$2:$J$670,$A18,'Raw Data'!$I$2:$I$670,$B18) -> 13.5
A19: THLCH | B19: LCH04 | C19: =COUNTIFS('Raw Data'!$J$2:$J$670,$A19,'Raw Data'!$I$2:$I$670,$B19) -> 239 | D19: =_xlfn.IFS(C19=0,0,C19>0,AVERAGEIFS('Raw Data'!$S$2:$S$670,'Raw Data'!$J$2:$J$670,$A19,'Raw Data'!$I$2:$I$670,$B19)) -> 3.9862619 | E19: =_xlfn.MAXIFS('Raw Data'!$S$2:$S$670,'Raw Data'!$J$2:$J$670,$A19,'Raw Data'!$I$2:$I$670,$B19) -> 27
A20: THLCH | B20: LCH05 | C20: =COUNTIFS('Raw Data'!$J$2:$J$670,$A20,'Raw Data'!$I$2:$I$670,$B20) -> 83 | D20: =_xlfn.IFS(C20=0,0,C20>0,AVERAGEIFS('Raw Data'!$S$2:$S$670,'Raw Data'!$J$2:$J$670,$A20,'Raw Data'!$I$2:$I$670,$B20)) -> 4.7064325 | E20: =_xlfn.MAXIFS('Raw Data'!$S$2:$S$670,'Raw Data'!$J$2:$J$670,$A20,'Raw Data'!$I$2:$I$670,$B20) -> 72
A21: THLCH | B21: LCH06 | C21: =COUNTIFS('Raw Data'!$J$2:$J$670,$A21,'Raw Data'!$I$2:$I$670,$B21) -> 4 | D21: =_xlfn.IFS(C21=0,0,C21>0,AVERAGEIFS('Raw Data'!$S$2:$S$670,'Raw Data'!$J$2:$J$670,$A21,'Raw Data'!$I$2:$I$670,$B21)) -> 0.9 | E21: =_xlfn.MAXIFS('Raw Data'!$S$2:$S$670,'Raw Data'!$J$2:$J$670,$A21,'Raw Data'!$I$2:$I$670,$B21) -> 1
A22: THLCH | B22: LCH07 | C22: =COUNTIFS('Raw Data'!$J$2:$J$670,$A22,'Raw Data'!$I$2:$I$670,$B22) -> 11 | D22: =_xlfn.IFS(C22=0,0,C22>0,AVERAGEIFS('Raw Data'!$S$2:$S$670,'Raw Data'!$J$2:$J$670,$A22,'Raw Data'!$I$2:$I$670,$B22)) -> 1.2363636 | E22: =_xlfn.MAXIFS('Raw Data'!$S$2:$S$670,'Raw Data'!$J$2:$J$670,$A22,'Raw Data'!$I$2:$I$670,$B22) -> 3
A23: THLCH | B23: LCH08 | C23: =COUNTIFS('Raw Data'!$J$2:$J$670,$A23,'Raw Data'!$I$2:$I$670,$B23) -> 3 | D23: =_xlfn.IFS(C23=0,0,C23>0,AVERAGEIFS('Raw Data'!$S$2:$S$670,'Raw Data'!$J$2:$J$670,$A23,'Raw Data'!$I$2:$I$670,$B23)) -> 9 | E23: =_xlfn.MAXIFS('Raw Data'!$S$2:$S$670,'Raw Data'!$J$2:$J$670,$A23,'Raw Data'!$I$2:$I$670,$B23) -> 25
A24: THLCH | B24: LCH10 | C24: =COUNTIFS('Raw Data'!$J$2:$J$670,$A24,'Raw Data'!$I$2:$I$670,$B24) -> 17 | D24: =_xlfn.IFS(C24=0,0,C24>0,AVERAGEIFS('Raw Data'!$S$2:$S$670,'Raw Data'!$J$2:$J$670,$A24,'Raw Data'!$I$2:$I$670,$B24)) -> 1.7647059 | E24: =_xlfn.MAXIFS('Raw Data'!$S$2:$S$670,'Raw Data'!$J$2:$J$670,$A24,'Raw Data'!$I$2:$I$670,$B24) -> 7

Sheet Service Summary
A1: Waiting Time by Service (Overall)
A3: Service | B3: Calls (Count) | C3: Avg Wait (Hrs) | D3: Median Wait (Hrs) | E3: Min Wait (Hrs) | F3: Max Wait (Hrs)
A4: KST | B4: =COUNTIF('Raw Data'!$A$2:$A$670,$A4) -> 100 | C4: =AVERAGEIF('Raw Data'!$A$2:$A$670,$A4,'Raw Data'!$S$2:$S$670) -> 3.547177 | D4: {=MEDIAN(IF('Raw Data'!$A$2:$A$670=$A4,'Raw Data'!$S$2:$S$670))} -> 1 | E4: =_xlfn.MINIFS('Raw Data'!$S$2:$S$670,'Raw Data'!$A$2:$A$670,$A4) -> 0.0167 | F4: =_xlfn.MAXIFS('Raw Data'!$S$2:$S$670,'Raw Data'!$A$2:$A$670,$A4) -> 72
A5: VTS | B5: =COUNTIF('Raw Data'!$A$2:$A$670,$A5) -> 94 | C5: =AVERAGEIF('Raw Data'!$A$2:$A$670,$A5,'Raw Data'!$S$2:$S$670) -> 6.1991117 | D5: {=MEDIAN(IF('Raw Data'!$A$2:$A$670=$A5,'Raw Data'!$S$2:$S$670))} -> 2.5333 | E5: =_xlfn.MINIFS('Raw Data'!$S$2:$S$670,'Raw Data'!$A$2:$A$670,$A5) -> 0.4333 | F5: =_xlfn.MAXIFS('Raw Data'!$S$2:$S$670,'Raw Data'!$A$2:$A$670,$A5) -> 41.8333
A6: NTX | B6: =COUNTIF('Raw Data'!$A$2:$A$670,$A6) -> 93 | C6: =AVERAGEIF('Raw Data'!$A$2:$A$670,$A6,'Raw Data'!$S$2:$S$670) -> 3.919714 | D6: {=MEDIAN(IF('Raw Data'!$A$2:$A$670=$A6,'Raw Data'!$S$2:$S$670))} -> 2 | E6: =_xlfn.MINIFS('Raw Data'!$S$2:$S$670,'Raw Data'!$A$2:$A$670,$A6) -> 0.0167 | F6: =_xlfn.MAXIFS('Raw Data'!$S$2:$S$670,'Raw Data'!$A$2:$A$670,$A6) -> 20.5
A7: KHS1 | B7: =COUNTIF('Raw Data'!$A$2:$A$670,$A7) -> 88 | C7: =AVERAGEIF('Raw Data'!$A$2:$A$670,$A7,'Raw Data'!$S$2:$S$670) -> 9.5202648 | D7: {=MEDIAN(IF('Raw Data'!$A$2:$A$670=$A7,'Raw Data'!$S$2:$S$670))} -> 3.91665 | E7: =_xlfn.MINIFS('Raw Data'!$S$2:$S$670,'Raw Data'!$A$2:$A$670,$A7) -> 0.5167 | F7: =_xlfn.MAXIFS('Raw Data'!$S$2:$S$670,'Raw Data'!$A$2:$A$670,$A7) -> 58
A8: CHT | B8: =COUNTIF('Raw Data'!$A$2:$A$670,$A8) -> 86 | C8: =AVERAGEIF('Raw Data'!$A$2:$A$670,$A8,'Raw Data'!$S$2:$S$670) -> 6.6976744 | D8: {=MEDIAN(IF('Raw Data'!$A$2:$A$670=$A8,'Raw Data'!$S$2:$S$670))} -> 3 | E8: =_xlfn.MINIFS('Raw Data'!$S$2:$S$670,'Raw Data'!$A$2:$A$670,$A8) -> 1 | F8: =_xlfn.MAXIFS('Raw Data'!$S$2:$S$670,'Raw Data'!$A$2:$A$670,$A8) -> 54
A9: KTS1 | B9: =COUNTIF('Raw Data'!$A$2:$A$670,$A9) -> 84 | C9: =AVERAGEIF('Raw Data'!$A$2:$A$670,$A9,'Raw Data'!$S$2:$S$670) -> 6.8426583 | D9: {=MEDIAN(IF('Raw Data'!$A$2:$A$670=$A9,'Raw Data'!$S$2:$S$670))} -> 3 | E9: =_xlfn.MINIFS('Raw Data'!$S$2:$S$670,'Raw Data'!$A$2:$A$670,$A9) -> 0.5 | F9: =_xlfn.MAXIFS('Raw Data'!$S$2:$S$670,'Raw Data'!$A$2:$A$670,$A9) -> 49
A10: BTS | B10: =COUNTIF('Raw Data'!$A$2:$A$670,$A10) -> 68 | C10: =AVERAGEIF('Raw Data'!$A$2:$A$670,$A10,'Raw Data'!$S$2:$S$670) -> 9.0264706 | D10: {=MEDIAN(IF('Raw Data'!$A$2:$A$670=$A10,'Raw Data'!$S$2:$S$670))} -> 4.3 | E10: =_xlfn.MINIFS('Raw Data'!$S$2:$S$670,'Raw Data'!$A$2:$A$670,$A10) -> 0 | F10: =_xlfn.MAXIFS('Raw Data'!$S$2:$S$670,'Raw Data'!$A$2:$A$670,$A10) -> 45
A11: ANX | B11: =COUNTIF('Raw Data'!$A$2:$A$670,$A11) -> 27 | C11: =AVERAGEIF('Raw Data'!$A$2:$A$670,$A11,'Raw Data'!$S$2:$S$670) -> 6.2444444 | D11: {=MEDIAN(IF('Raw Data'!$A$2:$A$670=$A11,'Raw Data'!$S$2:$S$670))} -> 4.9 | E11: =_xlfn.MINIFS('Raw Data'!$S$2:$S$670,'Raw Data'!$A$2:$A$670,$A11) -> 0.0167 | F11: =_xlfn.MAXIFS('Raw Data'!$S$2:$S$670,'Raw Data'!$A$2:$A$670,$A11) -> 25
A12: PCI2 | B12: =COUNTIF('Raw Data'!$A$2:$A$670,$A12) -> 27 | C12: =AVERAGEIF('Raw Data'!$A$2:$A$670,$A12,'Raw Data'!$S$2:$S$670) -> 1.9549444 | D12: {=MEDIAN(IF('Raw Data'!$A$2:$A$670=$A12,'Raw Data'!$S$2:$S$670))} -> 1 | E12: =_xlfn.MINIFS('Raw Data'!$S$2:$S$670,'Raw Data'!$A$2:$A$670,$A12) -> 0.0167 | F12: =_xlfn.MAXIFS('Raw Data'!$S$2:$S$670,'Raw Data'!$A$2:$A$670,$A12) -> 25
A13: EPS | B13: =COUNTIF('Raw Data'!$A$2:$A$670,$A13) -> 1 | C13: =AVERAGEIF('Raw Data'!$A$2:$A$670,$A13,'Raw Data'!$S$2:$S$670) -> 19.5 | D13: {=MEDIAN(IF('Raw Data'!$A$2:$A$670=$A13,'Raw Data'!$S$2:$S$670))} -> 19.5 | E13: =_xlfn.MINIFS('Raw Data'!$S$2:$S$670,'Raw Data'!$A$2:$A$670,$A13) -> 19.5 | F13: =_xlfn.MAXIFS('Raw Data'!$S$2:$S$670,'Raw Data'!$A$2:$A$670,$A13) -> 19.5
A14: ADHS | B14: =COUNTIF('Raw Data'!$A$2:$A$670,$A14) -> 1 | C14: =AVERAGEIF('Raw Data'!$A$2:$A$670,$A14,'Raw Data'!$S$2:$S$670) -> 25 | D14: {=MEDIAN(IF('Raw Data'!$A$2:$A$670=$A14,'Raw Data'!$S$2:$S$670))} -> 25 | E14: =_xlfn.MINIFS('Raw Data'!$S$2:$S$670,'Raw Data'!$A$2:$A$670,$A14) -> 25 | F14: =_xlfn.MAXIFS('Raw Data'!$S$2:$S$670,'Raw Data'!$A$2:$A$670,$A14) -> 25
A16: Note: ADHS and EPS have only 1 recorded call each — treat with caution (small sample).
A18: Waiting Time by Service × Terminal
A19: Service | B19: Terminal | C19: Calls (Count) | D19: Avg Wait (Hrs) | E19: Max Wait (Hrs)
A20: ADHS | B20: THLCH | C20: =COUNTIFS('Raw Data'!$A$2:$A$670,$A20,'Raw Data'!$J$2:$J$670,$B20) -> 1 | D20: =_xlfn.IFS(C20=0,0,C20>0,AVERAGEIFS('Raw Data'!$S$2:$S$670,'Raw Data'!$A$2:$A$670,$A20,'Raw Data'!$J$2:$J$670,$B20)) -> 25 | E20: =_xlfn.MAXIFS('Raw Data'!$S$2:$S$670,'Raw Data'!$A$2:$A$670,$A20,'Raw Data'!$J$2:$J$670,$B20) -> 25
A21: ANX | B21: THLCH | C21: =COUNTIFS('Raw Data'!$A$2:$A$670,$A21,'Raw Data'!$J$2:$J$670,$B21) -> 27 | D21: =_xlfn.IFS(C21=0,0,C21>0,AVERAGEIFS('Raw Data'!$S$2:$S$670,'Raw Data'!$A$2:$A$670,$A21,'Raw Data'!$J$2:$J$670,$B21)) -> 6.2444444 | E21: =_xlfn.MAXIFS('Raw Data'!$S$2:$S$670,'Raw Data'!$A$2:$A$670,$A21,'Raw Data'!$J$2:$J$670,$B21) -> 25
A22: BTS | B22: THBKK | C22: =COUNTIFS('Raw Data'!$A$2:$A$670,$A22,'Raw Data'!$J$2:$J$670,$B22) -> 23 | D22: =_xlfn.IFS(C22=0,0,C22>0,AVERAGEIFS('Raw Data'!$S$2:$S$670,'Raw Data'!$A$2:$A$670,$A22,'Raw Data'!$J$2:$J$670,$B22)) -> 15.278261 | E22: =_xlfn.MAXIFS('Raw Data'!$S$2:$S$670,'Raw Data'!$A$2:$A$670,$A22,'Raw Data'!$J$2:$J$670,$B22) -> 45
A23: BTS | B23: THLCH | C23: =COUNTIFS('Raw Data'!$A$2:$A$670,$A23,'Raw Data'!$J$2:$J$670,$B23) -> 45 | D23: =_xlfn.IFS(C23=0,0,C23>0,AVERAGEIFS('Raw Data'!$S$2:$S$670,'Raw Data'!$A$2:$A$670,$A23,'Raw Data'!$J$2:$J$670,$B23)) -> 5.8311111 | E23: =_xlfn.MAXIFS('Raw Data'!$S$2:$S$670,'Raw Data'!$A$2:$A$670,$A23,'Raw Data'!$J$2:$J$670,$B23) -> 40
A24: CHT | B24: THBKK | C24: =COUNTIFS('Raw Data'!$A$2:$A$670,$A24,'Raw Data'!$J$2:$J$670,$B24) -> 30 | D24: =_xlfn.IFS(C24=0,0,C24>0,AVERAGEIFS('Raw Data'!$S$2:$S$670,'Raw Data'!$A$2:$A$670,$A24,'Raw Data'!$J$2:$J$670,$B24)) -> 11.333333 | E24: =_xlfn.MAXIFS('Raw Data'!$S$2:$S$670,'Raw Data'!$A$2:$A$670,$A24,'Raw Data'!$J$2:$J$670,$B24) -> 36
A25: CHT | B25: THLCH | C25: =COUNTIFS('Raw Data'!$A$2:$A$670,$A25,'Raw Data'!$J$2:$J$670,$B25) -> 56 | D25: =_xlfn.IFS(C25=0,0,C25>0,AVERAGEIFS('Raw Data'!$S$2:$S$670,'Raw Data'!$A$2:$A$670,$A25,'Raw Data'!$J$2:$J$670,$B25)) -> 4.2142857 | E25: =_xlfn.MAXIFS('Raw Data'!$S$2:$S$670,'Raw Data'!$A$2:$A$670,$A25,'Raw Data'!$J$2:$J$670,$B25) -> 54
A26: EPS | B26: THBKK | C26: =COUNTIFS('Raw Data'!$A$2:$A$670,$A26,'Raw Data'!$J$2:$J$670,$B26) -> 1 | D26: =_xlfn.IFS(C26=0,0,C26>0,AVERAGEIFS('Raw Data'!$S$2:$S$670,'Raw Data'!$A$2:$A$670,$A26,'Raw Data'!$J$2:$J$670,$B26)) -> 19.5 | E26: =_xlfn.MAXIFS('Raw Data'!$S$2:$S$670,'Raw Data'!$A$2:$A$670,$A26,'Raw Data'!$J$2:$J$670,$B26) -> 19.5
A27: KHS1 | B27: THBKK | C27: =COUNTIFS('Raw Data'!$A$2:$A$670,$A27,'Raw Data'!$J$2:$J$670,$B27) -> 30 | D27: =_xlfn.IFS(C27=0,0,C27>0,AVERAGEIFS('Raw Data'!$S$2:$S$670,'Raw Data'!$A$2:$A$670,$A27,'Raw Data'!$J$2:$J$670,$B27)) -> 18.347777 | E27: =_xlfn.MAXIFS('Raw Data'!$S$2:$S$670,'Raw Data'!$A$2:$A$670,$A27,'Raw Data'!$J$2:$J$670,$B27) -> 58
A28: KHS1 | B28: THLCH | C28: =COUNTIFS('Raw Data'!$A$2:$A$670,$A28,'Raw Data'!$J$2:$J$670,$B28) -> 58 | D28: =_xlfn.IFS(C28=0,0,C28>0,AVERAGEIFS('Raw Data'!$S$2:$S$670,'Raw Data'!$A$2:$A$670,$A28,'Raw Data'!$J$2:$J$670,$B28)) -> 4.9543103 | E28: =_xlfn.MAXIFS('Raw Data'!$S$2:$S$670,'Raw Data'!$A$2:$A$670,$A28,'Raw Data'!$J$2:$J$670,$B28) -> 27
A29: KST | B29: THBKK | C29: =COUNTIFS('Raw Data'!$A$2:$A$670,$A29,'Raw Data'!$J$2:$J$670,$B29) -> 33 | D29: =_xlfn.IFS(C29=0,0,C29>0,AVERAGEIFS('Raw Data'!$S$2:$S$670,'Raw Data'!$A$2:$A$670,$A29,'Raw Data'!$J$2:$J$670,$B29)) -> 3.3116303 | E29: =_xlfn.MAXIFS('Raw Data'!$S$2:$S$670,'Raw Data'!$A$2:$A$670,$A29,'Raw Data'!$J$2:$J$670,$B29) -> 18
A30: KST | B30: THLCH | C30: =COUNTIFS('Raw Data'!$A$2:$A$670,$A30,'Raw Data'!$J$2:$J$670,$B30) -> 67 | D30: =_xlfn.IFS(C30=0,0,C30>0,AVERAGEIFS('Raw Data'!$S$2:$S$670,'Raw Data'!$A$2:$A$670,$A30,'Raw Data'!$J$2:$J$670,$B30)) -> 3.6631925 | E30: =_xlfn.MAXIFS('Raw Data'!$S$2:$S$670,'Raw Data'!$A$2:$A$670,$A30,'Raw Data'!$J$2:$J$670,$B30) -> 72
A31: KTS1 | B31: THBKK | C31: =COUNTIFS('Raw Data'!$A$2:$A$670,$A31,'Raw Data'!$J$2:$J$670,$B31) -> 30 | D31: =_xlfn.IFS(C31=0,0,C31>0,AVERAGEIFS('Raw Data'!$S$2:$S$670,'Raw Data'!$A$2:$A$670,$A31,'Raw Data'!$J$2:$J$670,$B31)) -> 14.569443 | E31: =_xlfn.MAXIFS('Raw Data'!$S$2:$S$670,'Raw Data'!$A$2:$A$670,$A31,'Raw Data'!$J$2:$J$670,$B31) -> 49
... A37: VTS | B37: THLCH | C37: =COUNTIFS('Raw Data'!$A$2:$A$670,$A37,'Raw Data'!$J$2:$J$670,$B37) -> 63 | D37: =_xlfn.IFS(C37=0,0,C37>0,AVERAGEIFS('Raw Data'!$S$2:$S$670,'Raw Data'!$A$2:$A$670,$A37,'Raw Data'!$J$2:$J$670,$B37)) -> 3.1772476 | E37: =_xlfn.MAXIFS('Raw Data'!$S$2:$S$670,'Raw Data'!$A$2:$A$670,$A37,'Raw Data'!$J$2:$J$670,$B37) -> 19

Sheet Operator Summary
A1: Waiting Time by Operator (Op.Liner)
A3: Operator (OPR) | B3: Calls (Count) | C3: Avg Wait (Hrs) | D3: Median Wait (Hrs) | E3: Min Wait (Hrs) | F3: Max Wait (Hrs)
A4: SKR | B4: =COUNTIF('Raw Data'!$D$2:$D$670,$A4) -> 284 | C4: =AVERAGEIF('Raw Data'!$D$2:$D$670,$A4,'Raw Data'!$S$2:$S$670) -> 6.9352113 | D4: {=MEDIAN(IF('Raw Data'!$D$2:$D$670=$A4,'Raw Data'!$S$2:$S$670))} -> 2 | E4: =_xlfn.MINIFS('Raw Data'!$S$2:$S$670,'Raw Data'!$D$2:$D$670,$A4) -> 0 | F4: =_xlfn.MAXIFS('Raw Data'!$S$2:$S$670,'Raw Data'!$D$2:$D$670,$A4) -> 58
A5: KMT | B5: =COUNTIF('Raw Data'!$D$2:$D$670,$A5) -> 168 | C5: =AVERAGEIF('Raw Data'!$D$2:$D$670,$A5,'Raw Data'!$S$2:$S$670) -> 6.3323417 | D5: {=MEDIAN(IF('Raw Data'!$D$2:$D$670=$A5,'Raw Data'!$S$2:$S$670))} -> 2 | E5: =_xlfn.MINIFS('Raw Data'!$S$2:$S$670,'Raw Data'!$D$2:$D$670,$A5) -> 0.0167 | F5: =_xlfn.MAXIFS('Raw Data'!$S$2:$S$670,'Raw Data'!$D$2:$D$670,$A5) -> 58
A6: CKL | B6: =COUNTIF('Raw Data'!$D$2:$D$670,$A6) -> 45 | C6: =AVERAGEIF('Raw Data'!$D$2:$D$670,$A6,'Raw Data'!$S$2:$S$670) -> 4.3466711 | D6: {=MEDIAN(IF('Raw Data'!$D$2:$D$670=$A6,'Raw Data'!$S$2:$S$670))} -> 1 | E6: =_xlfn.MINIFS('Raw Data'!$S$2:$S$670,'Raw Data'!$D$2:$D$670,$A6) -> 0.0167 | F6: =_xlfn.MAXIFS('Raw Data'!$S$2:$S$670,'Raw Data'!$D$2:$D$670,$A6) -> 23.5
A7: NAM | B7: =COUNTIF('Raw Data'!$D$2:$D$670,$A7) -> 40 | C7: =AVERAGEIF('Raw Data'!$D$2:$D$670,$A7,'Raw Data'!$S$2:$S$670) -> 5.3754175 | D7: {=MEDIAN(IF('Raw Data'!$D$2:$D$670=$A7,'Raw Data'!$S$2:$S$670))} -> 2 | E7: =_xlfn.MINIFS('Raw Data'!$S$2:$S$670,'Raw Data'!$D$2:$D$670,$A7) -> 0.0167 | F7: =_xlfn.MAXIFS('Raw Data'!$S$2:$S$670,'Raw Data'!$D$2:$D$670,$A7) -> 25
A8: HAS | B8: =COUNTIF('Raw Data'!$D$2:$D$670,$A8) -> 36 | C8: =AVERAGEIF('Raw Data'!$D$2:$D$670,$A8,'Raw Data'!$S$2:$S$670) -> 7.8171306 | D8: {=MEDIAN(IF('Raw Data'!$D$2:$D$670=$A8,'Raw Data'!$S$2:$S$670))} -> 2.55 | E8: =_xlfn.MINIFS('Raw Data'!$S$2:$S$670,'Raw Data'!$D$2:$D$670,$A8) -> 0.2 | F8: =_xlfn.MAXIFS('Raw Data'!$S$2:$S$670,'Raw Data'!$D$2:$D$670,$A8) -> 46
A9: DJS | B9: =COUNTIF('Raw Data'!$D$2:$D$670,$A9) -> 30 | C9: =AVERAGEIF('Raw Data'!$D$2:$D$670,$A9,'Raw Data'!$S$2:$S$670) -> 3.9844467 | D9: {=MEDIAN(IF('Raw Data'!$D$2:$D$670=$A9,'Raw Data'!$S$2:$S$670))} -> 2.25 | E9: =_xlfn.MINIFS('Raw Data'!$S$2:$S$670,'Raw Data'!$D$2:$D$670,$A9) -> 0.0167 | F9: =_xlfn.MAXIFS('Raw Data'!$S$2:$S$670,'Raw Data'!$D$2:$D$670,$A9) -> 20.5
A10: TSL | B10: =COUNTIF('Raw Data'!$D$2:$D$670,$A10) -> 27 | C10: =AVERAGEIF('Raw Data'!$D$2:$D$670,$A10,'Raw Data'!$S$2:$S$670) -> 5.4814815 | D10: {=MEDIAN(IF('Raw Data'!$D$2:$D$670=$A10,'Raw Data'!$S$2:$S$670))} -> 1 | E10: =_xlfn.MINIFS('Raw Data'!$S$2:$S$670,'Raw Data'!$D$2:$D$670,$A10) -> 1 | F10: =_xlfn.MAXIFS('Raw Data'!$S$2:$S$670,'Raw Data'!$D$2:$D$670,$A10) -> 36
A11: PCS | B11: =COUNTIF('Raw Data'!$D$2:$D$670,$A11) -> 24 | C11: =AVERAGEIF('Raw Data'!$D$2:$D$670,$A11,'Raw Data'!$S$2:$S$670) -> 6.5882125 | D11: {=MEDIAN(IF('Raw Data'!$D$2:$D$670=$A11,'Raw Data'!$S$2:$S$670))} -> 0.425 | E11: =_xlfn.MINIFS('Raw Data'!$S$2:$S$670,'Raw Data'!$D$2:$D$670,$A11) -> 0.0167 | F11: =_xlfn.MAXIFS('Raw Data'!$S$2:$S$670,'Raw Data'!$D$2:$D$670,$A11) -> 72
A12: PAN | B12: =COUNTIF('Raw Data'!$D$2:$D$670,$A12) -> 15 | C12: =AVERAGEIF('Raw Data'!$D$2:$D$670,$A12,'Raw Data'!$S$2:$S$670) -> 1.2733467 | D12: {=MEDIAN(IF('Raw Data'!$D$2:$D$670=$A12,'Raw Data'!$S$2:$S$670))} -> 0.9833 | E12: =_xlfn.MINIFS('Raw Data'!$S$2:$S$670,'Raw Data'!$D$2:$D$670,$A12) -> 0.0167 | F12: =_xlfn.MAXIFS('Raw Data'!$S$2:$S$670,'Raw Data'!$D$2:$D$670,$A12) -> 7
A15: Waiting Time by Operator × Terminal
A16: Operator (OPR) | B16: Terminal | C16: Calls (Count) | D16: Avg Wait (Hrs) | E16: Max Wait (Hrs)
A17: CKL | B17: THBKK | C17: =COUNTIFS('Raw Data'!$D$2:$D$670,$A17,'Raw Data'!$J$2:$J$670,$B17) -> 15 | D17: =_xlfn.IFS(C17=0,0,C17>0,AVERAGEIFS('Raw Data'!$S$2:$S$670,'Raw Data'!$D$2:$D$670,$A17,'Raw Data'!$J$2:$J$670,$B17)) -> 8.1700067 | E17: =_xlfn.MAXIFS('Raw Data'!$S$2:$S$670,'Raw Data'!$D$2:$D$670,$A17,'Raw Data'!$J$2:$J$670,$B17) -> 23.5
A18: CKL | B18: THLCH | C18: =COUNTIFS('Raw Data'!$D$2:$D$670,$A18,'Raw Data'!$J$2:$J$670,$B18) -> 30 | D18: =_xlfn.IFS(C18=0,0,C18>0,AVERAGEIFS('Raw Data'!$S$2:$S$670,'Raw Data'!$D$2:$D$670,$A18,'Raw Data'!$J$2:$J$670,$B18)) -> 2.4350033 | E18: =_xlfn.MAXIFS('Raw Data'!$S$2:$S$670,'Raw Data'!$D$2:$D$670,$A18,'Raw Data'!$J$2:$J$670,$B18) -> 15
A19: DJS | B19: THBKK | C19: =COUNTIFS('Raw Data'!$D$2:$D$670,$A19,'Raw Data'!$J$2:$J$670,$B19) -> 10 | D19: =_xlfn.IFS(C19=0,0,C19>0,AVERAGEIFS('Raw Data'!$S$2:$S$670,'Raw Data'!$D$2:$D$670,$A19,'Raw Data'!$J$2:$J$670,$B19)) -> 4.90167 | E19: =_xlfn.MAXIFS('Raw Data'!$S$2:$S$670,'Raw Data'!$D$2:$D$670,$A19,'Raw Data'!$J$2:$J$670,$B19) -> 20.5
A20: DJS | B20: THLCH | C20: =COUNTIFS('Raw Data'!$D$2:$D$670,$A20,'Raw Data'!$J$2:$J$670,$B20) -> 20 | D20: =_xlfn.IFS(C20=0,0,C20>0,AVERAGEIFS('Raw Data'!$S$2:$S$670,'Raw Data'!$D$2:$D$670,$A20,'Raw Data'!$J$2:$J$670,$B20)) -> 3.525835 | E20: =_xlfn.MAXIFS('Raw Data'!$S$2:$S$670,'Raw Data'!$D$2:$D$670,$A20,'Raw Data'!$J$2:$J$670,$B20) -> 14
A21: HAS | B21: THBKK | C21: =COUNTIFS('Raw Data'!$D$2:$D$670,$A21,'Raw Data'!$J$2:$J$670,$B21) -> 10 | D21: =_xlfn.IFS(C21=0,0,C21>0,AVERAGEIFS('Raw Data'!$S$2:$S$670,'Raw Data'!$D$2:$D$670,$A21,'Raw Data'!$J$2:$J$670,$B21)) -> 16.79 | E21: =_xlfn.MAXIFS('Raw Data'!$S$2:$S$670,'Raw Data'!$D$2:$D$670,$A21,'Raw Data'!$J$2:$J$670,$B21) -> 46
A22: HAS | B22: THLCH | C22: =COUNTIFS('Raw Data'!$D$2:$D$670,$A22,'Raw Data'!$J$2:$J$670,$B22) -> 26 | D22: =_xlfn.IFS(C22=0,0,C22>0,AVERAGEIFS('Raw Data'!$S$2:$S$670,'Raw Data'!$D$2:$D$670,$A22,'Raw Data'!$J$2:$J$670,$B22)) -> 4.3660269 | E22: =_xlfn.MAXIFS('Raw Data'!$S$2:$S$670,'Raw Data'!$D$2:$D$670,$A22,'Raw Data'!$J$2:$J$670,$B22) -> 27
A23: KMT | B23: THBKK | C23: =COUNTIFS('Raw Data'!$D$2:$D$670,$A23,'Raw Data'!$J$2:$J$670,$B23) -> 54 | D23: =_xlfn.IFS(C23=0,0,C23>0,AVERAGEIFS('Raw Data'!$S$2:$S$670,'Raw Data'!$D$2:$D$670,$A23,'Raw Data'!$J$2:$J$670,$B23)) -> 12.617593 | E23: =_xlfn.MAXIFS('Raw Data'!$S$2:$S$670,'Raw Data'!$D$2:$D$670,$A23,'Raw Data'!$J$2:$J$670,$B23) -> 58
A24: KMT | B24: THLCH | C24: =COUNTIFS('Raw Data'!$D$2:$D$670,$A24,'Raw Data'!$J$2:$J$670,$B24) -> 114 | D24: =_xlfn.IFS(C24=0,0,C24>0,AVERAGEIFS('Raw Data'!$S$2:$S$670,'Raw Data'!$D$2:$D$670,$A24,'Raw Data'!$J$2:$J$670,$B24)) -> 3.3551175 | E24: =_xlfn.MAXIFS('Raw Data'!$S$2:$S$670,'Raw Data'!$D$2:$D$670,$A24,'Raw Data'!$J$2:$J$670,$B24) -> 19
A25: NAM | B25: THBKK | C25: =COUNTIFS('Raw Data'!$D$2:$D$670,$A25,'Raw Data'!$J$2:$J$670,$B25) -> 11 | D25: =_xlfn.IFS(C25=0,0,C25>0,AVERAGEIFS('Raw Data'!$S$2:$S$670,'Raw Data'!$D$2:$D$670,$A25,'Raw Data'!$J$2:$J$670,$B25)) -> 6.2727273 | E25: =_xlfn.MAXIFS('Raw Data'!$S$2:$S$670,'Raw Data'!$D$2:$D$670,$A25,'Raw Data'!$J$2:$J$670,$B25) -> 17
A26: NAM | B26: THLCH | C26: =COUNTIFS('Raw Data'!$D$2:$D$670,$A26,'Raw Data'!$J$2:$J$670,$B26) -> 29 | D26: =_xlfn.IFS(C26=0,0,C26>0,AVERAGEIFS('Raw Data'!$S$2:$S$670,'Raw Data'!$D$2:$D$670,$A26,'Raw Data'!$J$2:$J$670,$B26)) -> 5.0350586 | E26: =_xlfn.MAXIFS('Raw Data'!$S$2:$S$670,'Raw Data'!$D$2:$D$670,$A26,'Raw Data'!$J$2:$J$670,$B26) -> 25
A27: PAN | B27: THBKK | C27: =COUNTIFS('Raw Data'!$D$2:$D$670,$A27,'Raw Data'!$J$2:$J$670,$B27) -> 5 | D27: =_xlfn.IFS(C27=0,0,C27>0,AVERAGEIFS('Raw Data'!$S$2:$S$670,'Raw Data'!$D$2:$D$670,$A27,'Raw Data'!$J$2:$J$670,$B27)) -> 1.21336 | E27: =_xlfn.MAXIFS('Raw Data'!$S$2:$S$670,'Raw Data'!$D$2:$D$670,$A27,'Raw Data'!$J$2:$J$670,$B27) -> 6
A28: PAN | B28: THLCH | C28: =COUNTIFS('Raw Data'!$D$2:$D$670,$A28,'Raw Data'!$J$2:$J$670,$B28) -> 10 | D28: =_xlfn.IFS(C28=0,0,C28>0,AVERAGEIFS('Raw Data'!$S$2:$S$670,'Raw Data'!$D$2:$D$670,$A28,'Raw Data'!$J$2:$J$670,$B28)) -> 1.30334 | E28: =_xlfn.MAXIFS('Raw Data'!$S$2:$S$670,'Raw Data'!$D$2:$D$670,$A28,'Raw Data'!$J$2:$J$670,$B28) -> 7
... A34: TSL | B34: THLCH | C34: =COUNTIFS('Raw Data'!$D$2:$D$670,$A34,'Raw Data'!$J$2:$J$670,$B34) -> 18 | D34: =_xlfn.IFS(C34=0,0,C34>0,AVERAGEIFS('Raw Data'!$S$2:$S$670,'Raw Data'!$D$2:$D$670,$A34,'Raw Data'!$J$2:$J$670,$B34)) -> 2.1666667 | E34: =_xlfn.MAXIFS('Raw Data'!$S$2:$S$670,'Raw Data'!$D$2:$D$670,$A34,'Raw Data'!$J$2:$J$670,$B34) -> 8

Sheet Monthly Trend
A1: Monthly Average Waiting Time by Terminal
A3: Month | B3: THBKK Avg Wait (Hrs) | C3: THLCH Avg Wait (Hrs) | D3: THBKK Calls | E3: THLCH Calls
A4: 2026-01 | B4: =IFERROR(AVERAGEIFS('Raw Data'!$S$2:$S$670,'Raw Data'!$T$2:$T$670,$A4,'Raw Data'!$J$2:$J$670,"THBKK"),0) -> 10.340003 | C4: =IFERROR(AVERAGEIFS('Raw Data'!$S$2:$S$670,'Raw Data'!$T$2:$T$670,$A4,'Raw Data'!$J$2:$J$670,"THLCH"),0) -> 3.0590197 | D4: =COUNTIFS('Raw Data'!$T$2:$T$670,$A4,'Raw Data'!$J$2:$J$670,"THBKK") -> 30 | E4: =COUNTIFS('Raw Data'!$T$2:$T$670,$A4,'Raw Data'!$J$2:$J$670,"THLCH") -> 61
A5: 2026-02 | B5: =IFERROR(AVERAGEIFS('Raw Data'!$S$2:$S$670,'Raw Data'!$T$2:$T$670,$A5,'Raw Data'!$J$2:$J$670,"THBKK"),0) -> 16.742668 | C5: =IFERROR(AVERAGEIFS('Raw Data'!$S$2:$S$670,'Raw Data'!$T$2:$T$670,$A5,'Raw Data'!$J$2:$J$670,"THLCH"),0) -> 4.1977981 | D5: =COUNTIFS('Raw Data'!$T$2:$T$670,$A5,'Raw Data'!$J$2:$J$670,"THBKK") -> 25 | E5: =COUNTIFS('Raw Data'!$T$2:$T$670,$A5,'Raw Data'!$J$2:$J$670,"THLCH") -> 53
A6: 2026-03 | B6: =IFERROR(AVERAGEIFS('Raw Data'!$S$2:$S$670,'Raw Data'!$T$2:$T$670,$A6,'Raw Data'!$J$2:$J$670,"THBKK"),0) -> 16.500642 | C6: =IFERROR(AVERAGEIFS('Raw Data'!$S$2:$S$670,'Raw Data'!$T$2:$T$670,$A6,'Raw Data'!$J$2:$J$670,"THLCH"),0) -> 6.5124236 | D6: =COUNTIFS('Raw Data'!$T$2:$T$670,$A6,'Raw Data'!$J$2:$J$670,"THBKK") -> 26 | E6: =COUNTIFS('Raw Data'!$T$2:$T$670,$A6,'Raw Data'!$J$2:$J$670,"THLCH") -> 55
A7: 2026-04 | B7: =IFERROR(AVERAGEIFS('Raw Data'!$S$2:$S$670,'Raw Data'!$T$2:$T$670,$A7,'Raw Data'!$J$2:$J$670,"THBKK"),0) -> 8.6362304 | C7: =IFERROR(AVERAGEIFS('Raw Data'!$S$2:$S$670,'Raw Data'!$T$2:$T$670,$A7,'Raw Data'!$J$2:$J$670,"THLCH"),0) -> 3.4345685 | D7: =COUNTIFS('Raw Data'!$T$2:$T$670,$A7,'Raw Data'!$J$2:$J$670,"THBKK") -> 23 | E7: =COUNTIFS('Raw Data'!$T$2:$T$670,$A7,'Raw Data'!$J$2:$J$670,"THLCH") -> 54
A8: 2026-05 | B8: =IFERROR(AVERAGEIFS('Raw Data'!$S$2:$S$670,'Raw Data'!$T$2:$T$670,$A8,'Raw Data'!$J$2:$J$670,"THBKK"),0) -> 8.2384654 | C8: =IFERROR(AVERAGEIFS('Raw Data'!$S$2:$S$670,'Raw Data'!$T$2:$T$670,$A8,'Raw Data'!$J$2:$J$670,"THLCH"),0) -> 4.1438632 | D8: =COUNTIFS('Raw Data'!$T$2:$T$670,$A8,'Raw Data'!$J$2:$J$670,"THBKK") -> 26 | E8: =COUNTIFS('Raw Data'!$T$2:$T$670,$A8,'Raw Data'!$J$2:$J$670,"THLCH") -> 57
A9: 2026-06 | B9: =IFERROR(AVERAGEIFS('Raw Data'!$S$2:$S$670,'Raw Data'!$T$2:$T$670,$A9,'Raw Data'!$J$2:$J$670,"THBKK"),0) -> 9.3791708 | C9: =IFERROR(AVERAGEIFS('Raw Data'!$S$2:$S$670,'Raw Data'!$T$2:$T$670,$A9,'Raw Data'!$J$2:$J$670,"THLCH"),0) -> 2.6065373 | D9: =COUNTIFS('Raw Data'!$T$2:$T$670,$A9,'Raw Data'!$J$2:$J$670,"THBKK") -> 24 | E9: =COUNTIFS('Raw Data'!$T$2:$T$670,$A9,'Raw Data'!$J$2:$J$670,"THLCH") -> 51
A10: 2026-07 | B10: =IFERROR(AVERAGEIFS('Raw Data'!$S$2:$S$670,'Raw Data'!$T$2:$T$670,$A10,'Raw Data'!$J$2:$J$670,"THBKK"),0) -> 13.517391 | C10: =IFERROR(AVERAGEIFS('Raw Data'!$S$2:$S$670,'Raw Data'!$T$2:$T$670,$A10,'Raw Data'!$J$2:$J$670,"THLCH"),0) -> 3.6574429 | D10: =COUNTIFS('Raw Data'!$T$2:$T$670,$A10,'Raw Data'!$J$2:$J$670,"THBKK") -> 23 | E10: =COUNTIFS('Raw Data'!$T$2:$T$670,$A10,'Raw Data'!$J$2:$J$670,"THLCH") -> 56
A11: 2026-08 | B11: =IFERROR(AVERAGEIFS('Raw Data'!$S$2:$S$670,'Raw Data'!$T$2:$T$670,$A11,'Raw Data'!$J$2:$J$670,"THBKK"),0) -> 8.1934783 | C11: =IFERROR(AVERAGEIFS('Raw Data'!$S$2:$S$670,'Raw Data'!$T$2:$T$670,$A11,'Raw Data'!$J$2:$J$670,"THLCH"),0) -> 4.8881836 | D11: =COUNTIFS('Raw Data'!$T$2:$T$670,$A11,'Raw Data'!$J$2:$J$670,"THBKK") -> 23 | E11: =COUNTIFS('Raw Data'!$T$2:$T$670,$A11,'Raw Data'!$J$2:$J$670,"THLCH") -> 55
A12: 2026-09 | B12: =IFERROR(AVERAGEIFS('Raw Data'!$S$2:$S$670,'Raw Data'!$T$2:$T$670,$A12,'Raw Data'!$J$2:$J$670,"THBKK"),0) -> 5.3 | C12: =IFERROR(AVERAGEIFS('Raw Data'!$S$2:$S$670,'Raw Data'!$T$2:$T$670,$A12,'Raw Data'!$J$2:$J$670,"THLCH"),0) -> 1.77315 | D12: =COUNTIFS('Raw Data'!$T$2:$T$670,$A12,'Raw Data'!$J$2:$J$670,"THBKK") -> 9 | E12: =COUNTIFS('Raw Data'!$T$2:$T$670,$A12,'Raw Data'!$J$2:$J$670,"THLCH") -> 18

Sheet Top 20 Longest Waits
A1: Top 20 Longest Berth Waiting Times (ETA → ETB)
A3: Rank | B3: Service | C3: Vessel | D3: Vessel Name | E3: Wharf | F3: Terminal | G3: POD | H3: ETA Date | I3: ETB Date | J3: Wait (Hrs)
A4: 1 | B4: =INDEX('Raw Data'!$A$2:$A$670,MATCH($A4,'Raw Data'!$U$2:$U$670,0)) -> KST | C4: =INDEX('Raw Data'!$B$2:$B$670,MATCH($A4,'Raw Data'!$U$2:$U$670,0)) -> PCCP | D4: =INDEX('Raw Data'!$C$2:$C$670,MATCH($A4,'Raw Data'!$U$2:$U$670,0)) -> PANCON CHAMPION | E4: =INDEX('Raw Data'!$I$2:$I$670,MATCH($A4,'Raw Data'!$U$2:$U$670,0)) -> LCH05 | F4: =INDEX('Raw Data'!$J$2:$J$670,MATCH($A4,'Raw Data'!$U$2:$U$670,0)) -> THLCH | G4: =INDEX('Raw Data'!$K$2:$K$670,MATCH($A4,'Raw Data'!$U$2:$U$670,0)) -> VNSGN | H4: =INDEX('Raw Data'!$P$2:$P$670,MATCH($A4,'Raw Data'!$U$2:$U$670,0)) -> 46112.208 | I4: =INDEX('Raw Data'!$Q$2:$Q$670,MATCH($A4,'Raw Data'!$U$2:$U$670,0)) -> 46115.208 | J4: =INDEX('Raw Data'!$S$2:$S$670,MATCH($A4,'Raw Data'!$U$2:$U$670,0)) -> 72
A5: 2 | B5: =INDEX('Raw Data'!$A$2:$A$670,MATCH($A5,'Raw Data'!$U$2:$U$670,0)) -> KHS1 | C5: =INDEX('Raw Data'!$B$2:$B$670,MATCH($A5,'Raw Data'!$U$2:$U$670,0)) -> KPN | D5: =INDEX('Raw Data'!$C$2:$C$670,MATCH($A5,'Raw Data'!$U$2:$U$670,0)) -> KMTC PUSAN | E5: =INDEX('Raw Data'!$I$2:$I$670,MATCH($A5,'Raw Data'!$U$2:$U$670,0)) -> BKK01 | F5: =INDEX('Raw Data'!$J$2:$J$670,MATCH($A5,'Raw Data'!$U$2:$U$670,0)) -> THBKK | G5: =INDEX('Raw Data'!$K$2:$K$670,MATCH($A5,'Raw Data'!$U$2:$U$670,0)) -> THLCH | H5: =INDEX('Raw Data'!$P$2:$P$670,MATCH($A5,'Raw Data'!$U$2:$U$670,0)) -> 46025.083 | I5: =INDEX('Raw Data'!$Q$2:$Q$670,MATCH($A5,'Raw Data'!$U$2:$U$670,0)) -> 46027.5 | J5: =INDEX('Raw Data'!$S$2:$S$670,MATCH($A5,'Raw Data'!$U$2:$U$670,0)) -> 58
A6: 3 | B6: =INDEX('Raw Data'!$A$2:$A$670,MATCH($A6,'Raw Data'!$U$2:$U$670,0)) -> KHS1 | C6: =INDEX('Raw Data'!$B$2:$B$670,MATCH($A6,'Raw Data'!$U$2:$U$670,0)) -> SWIC | D6: =INDEX('Raw Data'!$C$2:$C$670,MATCH($A6,'Raw Data'!$U$2:$U$670,0)) -> SAWASDEE INCHEON | E6: =INDEX('Raw Data'!$I$2:$I$670,MATCH($A6,'Raw Data'!$U$2:$U$670,0)) -> BKK01 | F6: =INDEX('Raw Data'!$J$2:$J$670,MATCH($A6,'Raw Data'!$U$2:$U$670,0)) -> THBKK | G6: =INDEX('Raw Data'!$K$2:$K$670,MATCH($A6,'Raw Data'!$U$2:$U$670,0)) -> THLCH | H6: =INDEX('Raw Data'!$P$2:$P$670,MATCH($A6,'Raw Data'!$U$2:$U$670,0)) -> 46062.917 | I6: =INDEX('Raw Data'!$Q$2:$Q$670,MATCH($A6,'Raw Data'!$U$2:$U$670,0)) -> 46065.333 | J6: =INDEX('Raw Data'!$S$2:$S$670,MATCH($A6,'Raw Data'!$U$2:$U$670,0)) -> 58
A7: 4 | B7: =INDEX('Raw Data'!$A$2:$A$670,MATCH($A7,'Raw Data'!$U$2:$U$670,0)) -> CHT | C7: =INDEX('Raw Data'!$B$2:$B$670,MATCH($A7,'Raw Data'!$U$2:$U$670,0)) -> SWMM | D7: =INDEX('Raw Data'!$C$2:$C$670,MATCH($A7,'Raw Data'!$U$2:$U$670,0)) -> SAWASDEE MIMOSA | E7: =INDEX('Raw Data'!$I$2:$I$670,MATCH($A7,'Raw Data'!$U$2:$U$670,0)) -> LCH05 | F7: =INDEX('Raw Data'!$J$2:$J$670,MATCH($A7,'Raw Data'!$U$2:$U$670,0)) -> THLCH | G7: =INDEX('Raw Data'!$K$2:$K$670,MATCH($A7,'Raw Data'!$U$2:$U$670,0)) -> HKHKG | H7: =INDEX('Raw Data'!$P$2:$P$670,MATCH($A7,'Raw Data'!$U$2:$U$670,0)) -> 46113.792 | I7: =INDEX('Raw Data'!$Q$2:$Q$670,MATCH($A7,'Raw Data'!$U$2:$U$670,0)) -> 46116.042 | J7: =INDEX('Raw Data'!$S$2:$S$670,MATCH($A7,'Raw Data'!$U$2:$U$670,0)) -> 54
A8: 5 | B8: =INDEX('Raw Data'!$A$2:$A$670,MATCH($A8,'Raw Data'!$U$2:$U$670,0)) -> KHS1 | C8: =INDEX('Raw Data'!$B$2:$B$670,MATCH($A8,'Raw Data'!$U$2:$U$670,0)) -> SWIC | D8: =INDEX('Raw Data'!$C$2:$C$670,MATCH($A8,'Raw Data'!$U$2:$U$670,0)) -> SAWASDEE INCHEON | E8: =INDEX('Raw Data'!$I$2:$I$670,MATCH($A8,'Raw Data'!$U$2:$U$670,0)) -> BKK01 | F8: =INDEX('Raw Data'!$J$2:$J$670,MATCH($A8,'Raw Data'!$U$2:$U$670,0)) -> THBKK | G8: =INDEX('Raw Data'!$K$2:$K$670,MATCH($A8,'Raw Data'!$U$2:$U$670,0)) -> THLCH | H8: =INDEX('Raw Data'!$P$2:$P$670,MATCH($A8,'Raw Data'!$U$2:$U$670,0)) -> 46231.708 | I8: =INDEX('Raw Data'!$Q$2:$Q$670,MATCH($A8,'Raw Data'!$U$2:$U$670,0)) -> 46233.875 | J8: =INDEX('Raw Data'!$S$2:$S$670,MATCH($A8,'Raw Data'!$U$2:$U$670,0)) -> 52
A9: 6 | B9: =INDEX('Raw Data'!$A$2:$A$670,MATCH($A9,'Raw Data'!$U$2:$U$670,0)) -> KTS1 | C9: =INDEX('Raw Data'!$B$2:$B$670,MATCH($A9,'Raw Data'!$U$2:$U$670,0)) -> KMTP | D9: =INDEX('Raw Data'!$C$2:$C$670,MATCH($A9,'Raw Data'!$U$2:$U$670,0)) -> KMTC TAIPEIS | E9: =INDEX('Raw Data'!$I$2:$I$670,MATCH($A9,'Raw Data'!$U$2:$U$670,0)) -> BKK01 | F9: =INDEX('Raw Data'!$J$2:$J$670,MATCH($A9,'Raw Data'!$U$2:$U$670,0)) -> THBKK | G9: =INDEX('Raw Data'!$K$2:$K$670,MATCH($A9,'Raw Data'!$U$2:$U$670,0)) -> THLCH | H9: =INDEX('Raw Data'!$P$2:$P$670,MATCH($A9,'Raw Data'!$U$2:$U$670,0)) -> 46062.292 | I9: =INDEX('Raw Data'!$Q$2:$Q$670,MATCH($A9,'Raw Data'!$U$2:$U$670,0)) -> 46064.333 | J9: =INDEX('Raw Data'!$S$2:$S$670,MATCH($A9,'Raw Data'!$U$2:$U$670,0)) -> 49
A10: 7 | B10: =INDEX('Raw Data'!$A$2:$A$670,MATCH($A10,'Raw Data'!$U$2:$U$670,0)) -> KST | C10: =INDEX('Raw Data'!$B$2:$B$670,MATCH($A10,'Raw Data'!$U$2:$U$670,0)) -> SWVG | D10: =INDEX('Raw Data'!$C$2:$C$670,MATCH($A10,'Raw Data'!$U$2:$U$670,0)) -> SAWASDEE VEGA | E10: =INDEX('Raw Data'!$I$2:$I$670,MATCH($A10,'Raw Data'!$U$2:$U$670,0)) -> LCH05 | F10: =INDEX('Raw Data'!$J$2:$J$670,MATCH($A10,'Raw Data'!$U$2:$U$670,0)) -> THLCH | G10: =INDEX('Raw Data'!$K$2:$K$670,MATCH($A10,'Raw Data'!$U$2:$U$670,0)) -> THBKK | H10: =INDEX('Raw Data'!$P$2:$P$670,MATCH($A10,'Raw Data'!$U$2:$U$670,0)) -> 46082.958 | I10: =INDEX('Raw Data'!$Q$2:$Q$670,MATCH($A10,'Raw Data'!$U$2:$U$670,0)) -> 46084.993 | J10: =INDEX('Raw Data'!$S$2:$S$670,MATCH($A10,'Raw Data'!$U$2:$U$670,0)) -> 48.8333
A11: 8 | B11: =INDEX('Raw Data'!$A$2:$A$670,MATCH($A11,'Raw Data'!$U$2:$U$670,0)) -> KHS1 | C11: =INDEX('Raw Data'!$B$2:$B$670,MATCH($A11,'Raw Data'!$U$2:$U$670,0)) -> SWIC | D11: =INDEX('Raw Data'!$C$2:$C$670,MATCH($A11,'Raw Data'!$U$2:$U$670,0)) -> SAWASDEE INCHEON | E11: =INDEX('Raw Data'!$I$2:$I$670,MATCH($A11,'Raw Data'!$U$2:$U$670,0)) -> BKK01 | F11: =INDEX('Raw Data'!$J$2:$J$670,MATCH($A11,'Raw Data'!$U$2:$U$670,0)) -> THBKK | G11: =INDEX('Raw Data'!$K$2:$K$670,MATCH($A11,'Raw Data'!$U$2:$U$670,0)) -> THLCH | H11: =INDEX('Raw Data'!$P$2:$P$670,MATCH($A11,'Raw Data'!$U$2:$U$670,0)) -> 46184.708 | I11: =INDEX('Raw Data'!$Q$2:$Q$670,MATCH($A11,'Raw Data'!$U$2:$U$670,0)) -> 46186.708 | J11: =INDEX('Raw Data'!$S$2:$S$670,MATCH($A11,'Raw Data'!$U$2:$U$670,0)) -> 48
A12: 9 | B12: =INDEX('Raw Data'!$A$2:$A$670,MATCH($A12,'Raw Data'!$U$2:$U$670,0)) -> KHS1 | C12: =INDEX('Raw Data'!$B$2:$B$670,MATCH($A12,'Raw Data'!$U$2:$U$670,0)) -> HAHM | D12: =INDEX('Raw Data'!$C$2:$C$670,MATCH($A12,'Raw Data'!$U$2:$U$670,0)) -> HEUNG-A HOCHIMINH | E12: =INDEX('Raw Data'!$I$2:$I$670,MATCH($A12,'Raw Data'!$U$2:$U$670,0)) -> BKK01 | F12: =INDEX('Raw Data'!$J$2:$J$670,MATCH($A12,'Raw Data'!$U$2:$U$670,0)) -> THBKK | G12: =INDEX('Raw Data'!$K$2:$K$670,MATCH($A12,'Raw Data'!$U$2:$U$670,0)) -> THLCH | H12: =INDEX('Raw Data'!$P$2:$P$670,MATCH($A12,'Raw Data'!$U$2:$U$670,0)) -> 46068.417 | I12: =INDEX('Raw Data'!$Q$2:$Q$670,MATCH($A12,'Raw Data'!$U$2:$U$670,0)) -> 46070.333 | J12: =INDEX('Raw Data'!$S$2:$S$670,MATCH($A12,'Raw Data'!$U$2:$U$670,0)) -> 46
A13: 10 | B13: =INDEX('Raw Data'!$A$2:$A$670,MATCH($A13,'Raw Data'!$U$2:$U$670,0)) -> BTS | C13: =INDEX('Raw Data'!$B$2:$B$670,MATCH($A13,'Raw Data'!$U$2:$U$670,0)) -> SWAT | D13: =INDEX('Raw Data'!$C$2:$C$670,MATCH($A13,'Raw Data'!$U$2:$U$670,0)) -> SAWASDEE ATLANTIC | E13: =INDEX('Raw Data'!$I$2:$I$670,MATCH($A13,'Raw Data'!$U$2:$U$670,0)) -> BKK04 | F13: =INDEX('Raw Data'!$J$2:$J$670,MATCH($A13,'Raw Data'!$U$2:$U$670,0)) -> THBKK | G13: =INDEX('Raw Data'!$K$2:$K$670,MATCH($A13,'Raw Data'!$U$2:$U$670,0)) -> THLCH | H13: =INDEX('Raw Data'!$P$2:$P$670,MATCH($A13,'Raw Data'!$U$2:$U$670,0)) -> 46063.5 | I13: =INDEX('Raw Data'!$Q$2:$Q$670,MATCH($A13,'Raw Data'!$U$2:$U$670,0)) -> 46065.375 | J13: =INDEX('Raw Data'!$S$2:$S$670,MATCH($A13,'Raw Data'!$U$2:$U$670,0)) -> 45
A14: 11 | B14: =INDEX('Raw Data'!$A$2:$A$670,MATCH($A14,'Raw Data'!$U$2:$U$670,0)) -> VTS | C14: =INDEX('Raw Data'!$B$2:$B$670,MATCH($A14,'Raw Data'!$U$2:$U$670,0)) -> KJT | D14: =INDEX('Raw Data'!$C$2:$C$670,MATCH($A14,'Raw Data'!$U$2:$U$670,0)) -> KMTC JAKARTA | E14: =INDEX('Raw Data'!$I$2:$I$670,MATCH($A14,'Raw Data'!$U$2:$U$670,0)) -> BKK01 | F14: =INDEX('Raw Data'!$J$2:$J$670,MATCH($A14,'Raw Data'!$U$2:$U$670,0)) -> THBKK | G14: =INDEX('Raw Data'!$K$2:$K$670,MATCH($A14,'Raw Data'!$U$2:$U$670,0)) -> THLCH | H14: =INDEX('Raw Data'!$P$2:$P$670,MATCH($A14,'Raw Data'!$U$2:$U$670,0)) -> 46062.25 | I14: =INDEX('Raw Data'!$Q$2:$Q$670,MATCH($A14,'Raw Data'!$U$2:$U$670,0)) -> 46063.993 | J14: =INDEX('Raw Data'!$S$2:$S$670,MATCH($A14,'Raw Data'!$U$2:$U$670,0)) -> 41.8333
A15: 12 | B15: =INDEX('Raw Data'!$A$2:$A$670,MATCH($A15,'Raw Data'!$U$2:$U$670,0)) -> KST | C15: =INDEX('Raw Data'!$B$2:$B$670,MATCH($A15,'Raw Data'!$U$2:$U$670,0)) -> PCCP | D15: =INDEX('Raw Data'!$C$2:$C$670,MATCH($A15,'Raw Data'!$U$2:$U$670,0)) -> PANCON CHAMPION | E15: =INDEX('Raw Data'!$I$2:$I$670,MATCH($A15,'Raw Data'!$U$2:$U$670,0)) -> LCH05 | F15: =INDEX('Raw Data'!$J$2:$J$670,MATCH($A15,'Raw Data'!$U$2:$U$670,0)) -> THLCH | G15: =INDEX('Raw Data'!$K$2:$K$670,MATCH($A15,'Raw Data'!$U$2:$U$670,0)) -> VNSGN | H15: =INDEX('Raw Data'!$P$2:$P$670,MATCH($A15,'Raw Data'!$U$2:$U$670,0)) -> 46227.708 | I15: =INDEX('Raw Data'!$Q$2:$Q$670,MATCH($A15,'Raw Data'!$U$2:$U$670,0)) -> 46229.413 | J15: =INDEX('Raw Data'!$S$2:$S$670,MATCH($A15,'Raw Data'!$U$2:$U$670,0)) -> 40.9167
... A23: 20 | B23: =INDEX('Raw Data'!$A$2:$A$670,MATCH($A23,'Raw Data'!$U$2:$U$670,0)) -> KTS1 | C23: =INDEX('Raw Data'!$B$2:$B$670,MATCH($A23,'Raw Data'!$U$2:$U$670,0)) -> KMGY | D23: =INDEX('Raw Data'!$C$2:$C$670,MATCH($A23,'Raw Data'!$U$2:$U$670,0)) -> KMTC GWANGYANG | E23: =INDEX('Raw Data'!$I$2:$I$670,MATCH($A23,'Raw Data'!$U$2:$U$670,0)) -> BKK01 | F23: =INDEX('Raw Data'!$J$2:$J$670,MATCH($A23,'Raw Data'!$U$2:$U$670,0)) -> THBKK | G23: =INDEX('Raw Data'!$K$2:$K$670,MATCH($A23,'Raw Data'!$U$2:$U$670,0)) -> THLCH | H23: =INDEX('Raw Data'!$P$2:$P$670,MATCH($A23,'Raw Data'!$U$2:$U$670,0)) -> 46024.125 | I23: =INDEX('Raw Data'!$Q$2:$Q$670,MATCH($A23,'Raw Data'!$U$2:$U$670,0)) -> 46025.375 | J23: =INDEX('Raw Data'!$S$2:$S$670,MATCH($A23,'Raw Data'!$U$2:$U$670,0)) -> 30

Sheet Wait Distribution
A1: Waiting Time Distribution by Terminal
A3: Terminal | B3: 0-1 Hrs | C3: 1-2 Hrs | D3: 2-4 Hrs | E3: 4-8 Hrs | F3: 8-24 Hrs | G3: >24 Hrs
A4: THBKK | B4: =COUNTIFS('Raw Data'!$J$2:$J$670,$A4,'Raw Data'!$S$2:$S$670,">="&0,'Raw Data'!$S$2:$S$670,"<="&1) -> 18 | C4: =COUNTIFS('Raw Data'!$J$2:$J$670,$A4,'Raw Data'!$S$2:$S$670,">"&1,'Raw Data'!$S$2:$S$670,"<="&2) -> 22 | D4: =COUNTIFS('Raw Data'!$J$2:$J$670,$A4,'Raw Data'!$S$2:$S$670,">"&2,'Raw Data'!$S$2:$S$670,"<="&4) -> 38 | E4: =COUNTIFS('Raw Data'!$J$2:$J$670,$A4,'Raw Data'!$S$2:$S$670,">"&4,'Raw Data'!$S$2:$S$670,"<="&8) -> 26 | F4: =COUNTIFS('Raw Data'!$J$2:$J$670,$A4,'Raw Data'!$S$2:$S$670,">"&8,'Raw Data'!$S$2:$S$670,"<="&24) -> 83 | G4: =COUNTIFS('Raw Data'!$J$2:$J$670,$A4,'Raw Data'!$S$2:$S$670,">"&24) -> 22
A5: THLCH | B5: =COUNTIFS('Raw Data'!$J$2:$J$670,$A5,'Raw Data'!$S$2:$S$670,">="&0,'Raw Data'!$S$2:$S$670,"<="&1) -> 284 | C5: =COUNTIFS('Raw Data'!$J$2:$J$670,$A5,'Raw Data'!$S$2:$S$670,">"&1,'Raw Data'!$S$2:$S$670,"<="&2) -> 30 | D5: =COUNTIFS('Raw Data'!$J$2:$J$670,$A5,'Raw Data'!$S$2:$S$670,">"&2,'Raw Data'!$S$2:$S$670,"<="&4) -> 32 | E5: =COUNTIFS('Raw Data'!$J$2:$J$670,$A5,'Raw Data'!$S$2:$S$670,">"&4,'Raw Data'!$S$2:$S$670,"<="&8) -> 49 | F5: =COUNTIFS('Raw Data'!$J$2:$J$670,$A5,'Raw Data'!$S$2:$S$670,">"&8,'Raw Data'!$S$2:$S$670,"<="&24) -> 53 | G5: =COUNTIFS('Raw Data'!$J$2:$J$670,$A5,'Raw Data'!$S$2:$S$670,">"&24) -> 12

Sheet Operational Insights
A1: Operational Insights — Beyond Berth Waiting Time
A3: 1. Root Cause — THBKK Wait Is Largely Tidal (Bangkok Bar), Not Operational
A4: Operational input: THBKK (Port of Bangkok / PAT) is a river terminal reached via the Chao Phraya river mouth ("Bangkok Bar"). Deep-draft vessels can only cross the bar around high tide, so they arrive (ETA) and then wait offshore for the next tide window before proceeding upriver to berth (ETB). THLCH (Laem Chabang) is a deep-sea terminal with no such restriction — confirmed below by the ETB (berthing) hour-of-day pattern.
A6: Hour of Day (ETB) | B6: THBKK % of Berthings | C6: THLCH % of Berthings | D6: THBKK Calls | E6: THLCH Calls
A7: 00:00 | B7: =COUNTIFS('Raw Data'!$Y$2:$Y$670,0,'Raw Data'!$J$2:$J$670,"THBKK")/COUNTIF('Raw Data'!$J$2:$J$670,"THBKK") -> 0.019138756 | C7: =COUNTIFS('Raw Data'!$Y$2:$Y$670,0,'Raw Data'!$J$2:$J$670,"THLCH")/COUNTIF('Raw Data'!$J$2:$J$670,"THLCH") -> 0.047826087 | D7: =COUNTIFS('Raw Data'!$Y$2:$Y$670,0,'Raw Data'!$J$2:$J$670,"THBKK") -> 4 | E7: =COUNTIFS('Raw Data'!$Y$2:$Y$670,0,'Raw Data'!$J$2:$J$670,"THLCH") -> 22
A8: 01:00 | B8: =COUNTIFS('Raw Data'!$Y$2:$Y$670,1,'Raw Data'!$J$2:$J$670,"THBKK")/COUNTIF('Raw Data'!$J$2:$J$670,"THBKK") -> 0.033492823 | C8: =COUNTIFS('Raw Data'!$Y$2:$Y$670,1,'Raw Data'!$J$2:$J$670,"THLCH")/COUNTIF('Raw Data'!$J$2:$J$670,"THLCH") -> 0.05 | D8: =COUNTIFS('Raw Data'!$Y$2:$Y$670,1,'Raw Data'!$J$2:$J$670,"THBKK") -> 7 | E8: =COUNTIFS('Raw Data'!$Y$2:$Y$670,1,'Raw Data'!$J$2:$J$670,"THLCH") -> 23
A9: 02:00 | B9: =COUNTIFS('Raw Data'!$Y$2:$Y$670,2,'Raw Data'!$J$2:$J$670,"THBKK")/COUNTIF('Raw Data'!$J$2:$J$670,"THBKK") -> 0.019138756 | C9: =COUNTIFS('Raw Data'!$Y$2:$Y$670,2,'Raw Data'!$J$2:$J$670,"THLCH")/COUNTIF('Raw Data'!$J$2:$J$670,"THLCH") -> 0.02826087 | D9: =COUNTIFS('Raw Data'!$Y$2:$Y$670,2,'Raw Data'!$J$2:$J$670,"THBKK") -> 4 | E9: =COUNTIFS('Raw Data'!$Y$2:$Y$670,2,'Raw Data'!$J$2:$J$670,"THLCH") -> 13
A10: 03:00 | B10: =COUNTIFS('Raw Data'!$Y$2:$Y$670,3,'Raw Data'!$J$2:$J$670,"THBKK")/COUNTIF('Raw Data'!$J$2:$J$670,"THBKK") -> 0.023923445 | C10: =COUNTIFS('Raw Data'!$Y$2:$Y$670,3,'Raw Data'!$J$2:$J$670,"THLCH")/COUNTIF('Raw Data'!$J$2:$J$670,"THLCH") -> 0.030434783 | D10: =COUNTIFS('Raw Data'!$Y$2:$Y$670,3,'Raw Data'!$J$2:$J$670,"THBKK") -> 5 | E10: =COUNTIFS('Raw Data'!$Y$2:$Y$670,3,'Raw Data'!$J$2:$J$670,"THLCH") -> 14
A11: 04:00 | B11: =COUNTIFS('Raw Data'!$Y$2:$Y$670,4,'Raw Data'!$J$2:$J$670,"THBKK")/COUNTIF('Raw Data'!$J$2:$J$670,"THBKK") -> 0.019138756 | C11: =COUNTIFS('Raw Data'!$Y$2:$Y$670,4,'Raw Data'!$J$2:$J$670,"THLCH")/COUNTIF('Raw Data'!$J$2:$J$670,"THLCH") -> 0.045652174 | D11: =COUNTIFS('Raw Data'!$Y$2:$Y$670,4,'Raw Data'!$J$2:$J$670,"THBKK") -> 4 | E11: =COUNTIFS('Raw Data'!$Y$2:$Y$670,4,'Raw Data'!$J$2:$J$670,"THLCH") -> 21
A12: 05:00 | B12: =COUNTIFS('Raw Data'!$Y$2:$Y$670,5,'Raw Data'!$J$2:$J$670,"THBKK")/COUNTIF('Raw Data'!$J$2:$J$670,"THBKK") -> 0.043062201 | C12: =COUNTIFS('Raw Data'!$Y$2:$Y$670,5,'Raw Data'!$J$2:$J$670,"THLCH")/COUNTIF('Raw Data'!$J$2:$J$670,"THLCH") -> 0.05 | D12: =COUNTIFS('Raw Data'!$Y$2:$Y$670,5,'Raw Data'!$J$2:$J$670,"THBKK") -> 9 | E12: =COUNTIFS('Raw Data'!$Y$2:$Y$670,5,'Raw Data'!$J$2:$J$670,"THLCH") -> 23
A13: 06:00 | B13: =COUNTIFS('Raw Data'!$Y$2:$Y$670,6,'Raw Data'!$J$2:$J$670,"THBKK")/COUNTIF('Raw Data'!$J$2:$J$670,"THBKK") -> 0.038277512 | C13: =COUNTIFS('Raw Data'!$Y$2:$Y$670,6,'Raw Data'!$J$2:$J$670,"THLCH")/COUNTIF('Raw Data'!$J$2:$J$670,"THLCH") -> 0.036956522 | D13: =COUNTIFS('Raw Data'!$Y$2:$Y$670,6,'Raw Data'!$J$2:$J$670,"THBKK") -> 8 | E13: =COUNTIFS('Raw Data'!$Y$2:$Y$670,6,'Raw Data'!$J$2:$J$670,"THLCH") -> 17
A14: 07:00 | B14: =COUNTIFS('Raw Data'!$Y$2:$Y$670,7,'Raw Data'!$J$2:$J$670,"THBKK")/COUNTIF('Raw Data'!$J$2:$J$670,"THBKK") -> 0.076555024 | C14: =COUNTIFS('Raw Data'!$Y$2:$Y$670,7,'Raw Data'!$J$2:$J$670,"THLCH")/COUNTIF('Raw Data'!$J$2:$J$670,"THLCH") -> 0.036956522 | D14: =COUNTIFS('Raw Data'!$Y$2:$Y$670,7,'Raw Data'!$J$2:$J$670,"THBKK") -> 16 | E14: =COUNTIFS('Raw Data'!$Y$2:$Y$670,7,'Raw Data'!$J$2:$J$670,"THLCH") -> 17
A15: 08:00 | B15: =COUNTIFS('Raw Data'!$Y$2:$Y$670,8,'Raw Data'!$J$2:$J$670,"THBKK")/COUNTIF('Raw Data'!$J$2:$J$670,"THBKK") -> 0.086124402 | C15: =COUNTIFS('Raw Data'!$Y$2:$Y$670,8,'Raw Data'!$J$2:$J$670,"THLCH")/COUNTIF('Raw Data'!$J$2:$J$670,"THLCH") -> 0.023913043 | D15: =COUNTIFS('Raw Data'!$Y$2:$Y$670,8,'Raw Data'!$J$2:$J$670,"THBKK") -> 18 | E15: =COUNTIFS('Raw Data'!$Y$2:$Y$670,8,'Raw Data'!$J$2:$J$670,"THLCH") -> 11
A16: 09:00 | B16: =COUNTIFS('Raw Data'!$Y$2:$Y$670,9,'Raw Data'!$J$2:$J$670,"THBKK")/COUNTIF('Raw Data'!$J$2:$J$670,"THBKK") -> 0.04784689 | C16: =COUNTIFS('Raw Data'!$Y$2:$Y$670,9,'Raw Data'!$J$2:$J$670,"THLCH")/COUNTIF('Raw Data'!$J$2:$J$670,"THLCH") -> 0.047826087 | D16: =COUNTIFS('Raw Data'!$Y$2:$Y$670,9,'Raw Data'!$J$2:$J$670,"THBKK") -> 10 | E16: =COUNTIFS('Raw Data'!$Y$2:$Y$670,9,'Raw Data'!$J$2:$J$670,"THLCH") -> 22
A17: 10:00 | B17: =COUNTIFS('Raw Data'!$Y$2:$Y$670,10,'Raw Data'!$J$2:$J$670,"THBKK")/COUNTIF('Raw Data'!$J$2:$J$670,"THBKK") -> 0.038277512 | C17: =COUNTIFS('Raw Data'!$Y$2:$Y$670,10,'Raw Data'!$J$2:$J$670,"THLCH")/COUNTIF('Raw Data'!$J$2:$J$670,"THLCH") -> 0.034782609 | D17: =COUNTIFS('Raw Data'!$Y$2:$Y$670,10,'Raw Data'!$J$2:$J$670,"THBKK") -> 8 | E17: =COUNTIFS('Raw Data'!$Y$2:$Y$670,10,'Raw Data'!$J$2:$J$670,"THLCH") -> 16
A18: 11:00 | B18: =COUNTIFS('Raw Data'!$Y$2:$Y$670,11,'Raw Data'!$J$2:$J$670,"THBKK")/COUNTIF('Raw Data'!$J$2:$J$670,"THBKK") -> 0.019138756 | C18: =COUNTIFS('Raw Data'!$Y$2:$Y$670,11,'Raw Data'!$J$2:$J$670,"THLCH")/COUNTIF('Raw Data'!$J$2:$J$670,"THLCH") -> 0.058695652 | D18: =COUNTIFS('Raw Data'!$Y$2:$Y$670,11,'Raw Data'!$J$2:$J$670,"THBKK") -> 4 | E18: =COUNTIFS('Raw Data'!$Y$2:$Y$670,11,'Raw Data'!$J$2:$J$670,"THLCH") -> 27
A19: 12:00 | B19: =COUNTIFS('Raw Data'!$Y$2:$Y$670,12,'Raw Data'!$J$2:$J$670,"THBKK")/COUNTIF('Raw Data'!$J$2:$J$670,"THBKK") -> 0.023923445 | C19: =COUNTIFS('Raw Data'!$Y$2:$Y$670,12,'Raw Data'!$J$2:$J$670,"THLCH")/COUNTIF('Raw Data'!$J$2:$J$670,"THLCH") -> 0.036956522 | D19: =COUNTIFS('Raw Data'!$Y$2:$Y$670,12,'Raw Data'!$J$2:$J$670,"THBKK") -> 5 | E19: =COUNTIFS('Raw Data'!$Y$2:$Y$670,12,'Raw Data'!$J$2:$J$670,"THLCH") -> 17
A20: 13:00 | B20: =COUNTIFS('Raw Data'!$Y$2:$Y$670,13,'Raw Data'!$J$2:$J$670,"THBKK")/COUNTIF('Raw Data'!$J$2:$J$670,"THBKK") -> 0.019138756 | C20: =COUNTIFS('Raw Data'!$Y$2:$Y$670,13,'Raw Data'!$J$2:$J$670,"THLCH")/COUNTIF('Raw Data'!$J$2:$J$670,"THLCH") -> 0.043478261 | D20: =COUNTIFS('Raw Data'!$Y$2:$Y$670,13,'Raw Data'!$J$2:$J$670,"THBKK") -> 4 | E20: =COUNTIFS('Raw Data'!$Y$2:$Y$670,13,'Raw Data'!$J$2:$J$670,"THLCH") -> 20
A21: 14:00 | B21: =COUNTIFS('Raw Data'!$Y$2:$Y$670,14,'Raw Data'!$J$2:$J$670,"THBKK")/COUNTIF('Raw Data'!$J$2:$J$670,"THBKK") -> 0.004784689 | C21: =COUNTIFS('Raw Data'!$Y$2:$Y$670,14,'Raw Data'!$J$2:$J$670,"THLCH")/COUNTIF('Raw Data'!$J$2:$J$670,"THLCH") -> 0.041304348 | D21: =COUNTIFS('Raw Data'!$Y$2:$Y$670,14,'Raw Data'!$J$2:$J$670,"THBKK") -> 1 | E21: =COUNTIFS('Raw Data'!$Y$2:$Y$670,14,'Raw Data'!$J$2:$J$670,"THLCH") -> 19
A22: 15:00 | B22: =COUNTIFS('Raw Data'!$Y$2:$Y$670,15,'Raw Data'!$J$2:$J$670,"THBKK")/COUNTIF('Raw Data'!$J$2:$J$670,"THBKK") -> 0.019138756 | C22: =COUNTIFS('Raw Data'!$Y$2:$Y$670,15,'Raw Data'!$J$2:$J$670,"THLCH")/COUNTIF('Raw Data'!$J$2:$J$670,"THLCH") -> 0.023913043 | D22: =COUNTIFS('Raw Data'!$Y$2:$Y$670,15,'Raw Data'!$J$2:$J$670,"THBKK") -> 4 | E22: =COUNTIFS('Raw Data'!$Y$2:$Y$670,15,'Raw Data'!$J$2:$J$670,"THLCH") -> 11
A23: 16:00 | B23: =COUNTIFS('Raw Data'!$Y$2:$Y$670,16,'Raw Data'!$J$2:$J$670,"THBKK")/COUNTIF('Raw Data'!$J$2:$J$670,"THBKK") -> 0.028708134 | C23: =COUNTIFS('Raw Data'!$Y$2:$Y$670,16,'Raw Data'!$J$2:$J$670,"THLCH")/COUNTIF('Raw Data'!$J$2:$J$670,"THLCH") -> 0.02826087 | D23: =COUNTIFS('Raw Data'!$Y$2:$Y$670,16,'Raw Data'!$J$2:$J$670,"THBKK") -> 6 | E23: =COUNTIFS('Raw Data'!$Y$2:$Y$670,16,'Raw Data'!$J$2:$J$670,"THLCH") -> 13
A24: 17:00 | B24: =COUNTIFS('Raw Data'!$Y$2:$Y$670,17,'Raw Data'!$J$2:$J$670,"THBKK")/COUNTIF('Raw Data'!$J$2:$J$670,"THBKK") -> 0.033492823 | C24: =COUNTIFS('Raw Data'!$Y$2:$Y$670,17,'Raw Data'!$J$2:$J$670,"THLCH")/COUNTIF('Raw Data'!$J$2:$J$670,"THLCH") -> 0.052173913 | D24: =COUNTIFS('Raw Data'!$Y$2:$Y$670,17,'Raw Data'!$J$2:$J$670,"THBKK") -> 7 | E24: =COUNTIFS('Raw Data'!$Y$2:$Y$670,17,'Raw Data'!$J$2:$J$670,"THLCH") -> 24
A25: 18:00 | B25: =COUNTIFS('Raw Data'!$Y$2:$Y$670,18,'Raw Data'!$J$2:$J$670,"THBKK")/COUNTIF('Raw Data'!$J$2:$J$670,"THBKK") -> 0.043062201 | C25: =COUNTIFS('Raw Data'!$Y$2:$Y$670,18,'Raw Data'!$J$2:$J$670,"THLCH")/COUNTIF('Raw Data'!$J$2:$J$670,"THLCH") -> 0.039130435 | D25: =COUNTIFS('Raw Data'!$Y$2:$Y$670,18,'Raw Data'!$J$2:$J$670,"THBKK") -> 9 | E25: =COUNTIFS('Raw Data'!$Y$2:$Y$670,18,'Raw Data'!$J$2:$J$670,"THLCH") -> 18
A26: 19:00 | B26: =COUNTIFS('Raw Data'!$Y$2:$Y$670,19,'Raw Data'!$J$2:$J$670,"THBKK")/COUNTIF('Raw Data'!$J$2:$J$670,"THBKK") -> 0.057416268 | C26: =COUNTIFS('Raw Data'!$Y$2:$Y$670,19,'Raw Data'!$J$2:$J$670,"THLCH")/COUNTIF('Raw Data'!$J$2:$J$670,"THLCH") -> 0.043478261 | D26: =COUNTIFS('Raw Data'!$Y$2:$Y$670,19,'Raw Data'!$J$2:$J$670,"THBKK") -> 12 | E26: =COUNTIFS('Raw Data'!$Y$2:$Y$670,19,'Raw Data'!$J$2:$J$670,"THLCH") -> 20
A27: 20:00 | B27: =COUNTIFS('Raw Data'!$Y$2:$Y$670,20,'Raw Data'!$J$2:$J$670,"THBKK")/COUNTIF('Raw Data'!$J$2:$J$670,"THBKK") -> 0.071770335 | C27: =COUNTIFS('Raw Data'!$Y$2:$Y$670,20,'Raw Data'!$J$2:$J$670,"THLCH")/COUNTIF('Raw Data'!$J$2:$J$670,"THLCH") -> 0.054347826 | D27: =COUNTIFS('Raw Data'!$Y$2:$Y$670,20,'Raw Data'!$J$2:$J$670,"THBKK") -> 15 | E27: =COUNTIFS('Raw Data'!$Y$2:$Y$670,20,'Raw Data'!$J$2:$J$670,"THLCH") -> 25
A28: 21:00 | B28: =COUNTIFS('Raw Data'!$Y$2:$Y$670,21,'Raw Data'!$J$2:$J$670,"THBKK")/COUNTIF('Raw Data'!$J$2:$J$670,"THBKK") -> 0.10047847 | C28: =COUNTIFS('Raw Data'!$Y$2:$Y$670,21,'Raw Data'!$J$2:$J$670,"THLCH")/COUNTIF('Raw Data'!$J$2:$J$670,"THLCH") -> 0.045652174 | D28: =COUNTIFS('Raw Data'!$Y$2:$Y$670,21,'Raw Data'!$J$2:$J$670,"THBKK") -> 21 | E28: =COUNTIFS('Raw Data'!$Y$2:$Y$670,21,'Raw Data'!$J$2:$J$670,"THLCH") -> 21
A29: 22:00 | B29: =COUNTIFS('Raw Data'!$Y$2:$Y$670,22,'Raw Data'!$J$2:$J$670,"THBKK")/COUNTIF('Raw Data'!$J$2:$J$670,"THBKK") -> 0.076555024 | C29: =COUNTIFS('Raw Data'!$Y$2:$Y$670,22,'Raw Data'!$J$2:$J$670,"THLCH")/COUNTIF('Raw Data'!$J$2:$J$670,"THLCH") -> 0.05 | D29: =COUNTIFS('Raw Data'!$Y$2:$Y$670,22,'Raw Data'!$J$2:$J$670,"THBKK") -> 16 | E29: =COUNTIFS('Raw Data'!$Y$2:$Y$670,22,'Raw Data'!$J$2:$J$670,"THLCH") -> 23
A30: 23:00 | B30: =COUNTIFS('Raw Data'!$Y$2:$Y$670,23,'Raw Data'!$J$2:$J$670,"THBKK")/COUNTIF('Raw Data'!$J$2:$J$670,"THBKK") -> 0.057416268 | C30: =COUNTIFS('Raw Data'!$Y$2:$Y$670,23,'Raw Data'!$J$2:$J$670,"THLCH")/COUNTIF('Raw Data'!$J$2:$J$670,"THLCH") -> 0.05 | D30: =COUNTIFS('Raw Data'!$Y$2:$Y$670,23,'Raw Data'!$J$2:$J$670,"THBKK") -> 12 | E30: =COUNTIFS('Raw Data'!$Y$2:$Y$670,23,'Raw Data'!$J$2:$J$670,"THLCH") -> 23
A32: THBKK berthings cluster into two ~4-hour windows roughly 12–13 hours apart (a semi-diurnal tide signature); THLCH berthings are spread evenly across the day. Practical implication: berth-productivity fixes (e.g. reallocating BKK01 traffic) will help less than tide-aware ETA planning — scheduling vessel arrival closer to the next tide window instead of arriving early and idling reduces reported waiting time directly.
A35: 2. Total Port Time Breakdown — Wait vs. Berth Occupancy
A36: Terminal | B36: Calls (Count) | C36: Avg Wait (Hrs) | D36: Avg Berth Occupancy (Hrs) | E36: Avg Total Port Stay (Hrs) | F36: Wait Share of Port Stay (%)
A37: THBKK | B37: =COUNTIF('Raw Data'!$J$2:$J$670,$A37) -> 209 | C37: =AVERAGEIF('Raw Data'!$J$2:$J$670,$A37,'Raw Data'!$S$2:$S$670) -> 11.209411 | D37: =AVERAGEIF('Raw Data'!$J$2:$J$670,$A37,'Raw Data'!$V$2:$V$670) -> 29.725601 | E37: =AVERAGEIF('Raw Data'!$J$2:$J$670,$A37,'Raw Data'!$W$2:$W$670) -> 40.935004 | F37: =C37/E37 -> 0.27383438
A38: THLCH | B38: =COUNTIF('Raw Data'!$J$2:$J$670,$A38) -> 460 | C38: =AVERAGEIF('Raw Data'!$J$2:$J$670,$A38,'Raw Data'!$S$2:$S$670) -> 3.9727189 | D38: =AVERAGEIF('Raw Data'!$J$2:$J$670,$A38,'Raw Data'!$V$2:$V$670) -> 10.451016 | E38: =AVERAGEIF('Raw Data'!$J$2:$J$670,$A38,'Raw Data'!$W$2:$W$670) -> 14.42373 | F38: =C38/E38 -> 0.27542938
A39: Port Stay = ETD − ETA (full turnaround). Occupancy = ETD − ETB (time actually at berth working cargo).
A42: 3. Waiting Time by Sailing Direction (Bound)
A43: Bound | B43: Meaning | C43: Calls (Count) | D43: Avg Wait (Hrs) | E43: Median Wait (Hrs)
A44: N | B44: Northbound | C44: =COUNTIF('Raw Data'!$G$2:$G$670,$A44) -> 436 | D44: =AVERAGEIF('Raw Data'!$G$2:$G$670,$A44,'Raw Data'!$S$2:$S$670) -> 8.1735867 | E44: {=MEDIAN(IF('Raw Data'!$G$2:$G$670=$A44,'Raw Data'!$S$2:$S$670))} -> 4
A45: S | B45: Southbound | C45: =COUNTIF('Raw Data'!$G$2:$G$670,$A45) -> 232 | D45: =AVERAGEIF('Raw Data'!$G$2:$G$670,$A45,'Raw Data'!$S$2:$S$670) -> 2.5066116 | E45: {=MEDIAN(IF('Raw Data'!$G$2:$G$670=$A45,'Raw Data'!$S$2:$S$670))} -> 1
A48: 4. Waiting Time by Day of Week (ETA)
A49: Day | B49: THBKK Avg Wait (Hrs) | C49: THLCH Avg Wait (Hrs) | D49: THBKK Calls | E49: THLCH Calls
...

Sheet Raw Data
A1: Service | B1: Vessel | C1: Vessel Name | D1: Op.Liner | E1: Seq | F1: Vyg | G1: Bound | H1: Vyg Bound | I1: Wharf | J1: Terminal (POL) | K1: POD | L1: Skip | M1: No D | N1: No L | O1: USED | P1: ETA Date | Q1: ETB Date | R1: ETD Date | S1: Wait (Hrs) | T1: Month | U1: Wait Rank | V1: Berth Occupancy (Hrs) | W1: Port Stay (Hrs) | X1: Day of Week | Y1: ETB Hour
A2: KST | B2: SWPC | C2: SAWASDEE PACIFIC | D2: SKR | E2: 06 | F2: 2522 | G2: N | H2: 2522N | I2: LCH05 | J2: THLCH | K2: VNSGN | L2: N | M2: N | N2: N | P2: 46023.25 | Q2: 46023.292 | R2: 46023.496 | S2: =ROUND((Q2-P2)*24,4) -> 1 | T2: =TEXT(P2,"YYYY-MM") -> 2026-01 | U2: =RANK(S2,$S$2:$S$670)+COUNTIF($S$2:S2,S2)-1 -> 368 | V2: =ROUND((R2-Q2)*24,4) -> 4.9 | W2: =ROUND((R2-P2)*24,4) -> 5.9 | X2: =TEXT(P2,"dddd") -> Thursday | Y2: =HOUR(Q2) -> 7
A3: KTS1 | B3: KMGY | C3: KMTC GWANGYANG | D3: KMT | E3: 05 | F3: 2513 | G3: S | H3: 2513S | I3: LCH04 | J3: THLCH | K3: THBKK | L3: N | M3: N | N3: N | P3: 46023.583 | Q3: 46023.625 | R3: 46024.042 | S3: =ROUND((Q3-P3)*24,4) -> 1 | T3: =TEXT(P3,"YYYY-MM") -> 2026-01 | U3: =RANK(S3,$S$2:$S$670)+COUNTIF($S$2:S3,S3)-1 -> 369 | V3: =ROUND((R3-Q3)*24,4) -> 10 | W3: =ROUND((R3-P3)*24,4) -> 11 | X3: =TEXT(P3,"dddd") -> Thursday | Y3: =HOUR(Q3) -> 15
A4: KTS1 | B4: KMGY | C4: KMTC GWANGYANG | D4: KMT | E4: 06 | F4: 2513 | G4: N | H4: 2513N | I4: BKK01 | J4: THBKK | K4: THLCH | L4: N | M4: N | N4: N | P4: 46024.125 | Q4: 46025.375 | R4: 46026.5 | S4: =ROUND((Q4-P4)*24,4) -> 30 | T4: =TEXT(P4,"YYYY-MM") -> 2026-01 | U4: =RANK(S4,$S$2:$S$670)+COUNTIF($S$2:S4,S4)-1 -> 20 | V4: =ROUND((R4-Q4)*24,4) -> 27 | W4: =ROUND((R4-P4)*24,4) -> 57 | X4: =TEXT(P4,"dddd") -> Friday | Y4: =HOUR(Q4) -> 9
A5: KHS1 | B5: KPN | C5: KMTC PUSAN | D5: KMT | E5: 06 | F5: 2514 | G5: S | H5: 2514S | I5: LCH01 | J5: THLCH | K5: THBKK | L5: N | M5: N | N5: N | P5: 46024.667 | Q5: 46024.708 | R5: 46024.996 | S5: =ROUND((Q5-P5)*24,4) -> 1 | T5: =TEXT(P5,"YYYY-MM") -> 2026-01 | U5: =RANK(S5,$S$2:$S$670)+COUNTIF($S$2:S5,S5)-1 -> 370 | V5: =ROUND((R5-Q5)*24,4) -> 6.9 | W5: =ROUND((R5-P5)*24,4) -> 7.9 | X5: =TEXT(P5,"dddd") -> Friday | Y5: =HOUR(Q5) -> 17
A6: NTX | B6: PGPO | C6: PEGASUS PROTO | D6: NAM | E6: 06 | F6: 2514 | G6: S | H6: 2514S | I6: LCH04 | J6: THLCH | K6: THBKK | L6: N | M6: N | N6: N | P6: 46024.958 | Q6: 46025 | R6: 46025.25 | S6: =ROUND((Q6-P6)*24,4) -> 1 | T6: =TEXT(P6,"YYYY-MM") -> 2026-01 | U6: =RANK(S6,$S$2:$S$670)+COUNTIF($S$2:S6,S6)-1 -> 371 | V6: =ROUND((R6-Q6)*24,4) -> 6 | W6: =ROUND((R6-P6)*24,4) -> 7 | X6: =TEXT(P6,"dddd") -> Friday | Y6: =HOUR(Q6) -> 0
A7: KHS1 | B7: KPN | C7: KMTC PUSAN | D7: KMT | E7: 07 | F7: 2514 | G7: N | H7: 2514N | I7: BKK01 | J7: THBKK | K7: THLCH | L7: N | M7: N | N7: N | P7: 46025.083 | Q7: 46027.5 | R7: 46029.208 | S7: =ROUND((Q7-P7)*24,4) -> 58 | T7: =TEXT(P7,"YYYY-MM") -> 2026-01 | U7: =RANK(S7,$S$2:$S$670)+COUNTIF($S$2:S7,S7)-1 -> 2 | V7: =ROUND((R7-Q7)*24,4) -> 41 | W7: =ROUND((R7-P7)*24,4) -> 99 | X7: =TEXT(P7,"dddd") -> Saturday | Y7: =HOUR(Q7) -> 12
A8: NTX | B8: PGPO | C8: PEGASUS PROTO | D8: NAM | E8: 07 | F8: 2514 | G8: N | H8: 2514N | I8: BKK02 | J8: THBKK | K8: THLCH | L8: N | M8: N | N8: N | P8: 46025.333 | Q8: 46025.417 | R8: 46026.229 | S8: =ROUND((Q8-P8)*24,4) -> 2 | T8: =TEXT(P8,"YYYY-MM") -> 2026-01 | U8: =RANK(S8,$S$2:$S$670)+COUNTIF($S$2:S8,S8)-1 -> 316 | V8: =ROUND((R8-Q8)*24,4) -> 19.5 | W8: =ROUND((R8-P8)*24,4) -> 21.5 | X8: =TEXT(P8,"dddd") -> Saturday | Y8: =HOUR(Q8) -> 10
A9: ANX | B9: NSSJ | C9: STARSHIP JUPITER | D9: NAM | E9: 06 | F9: 2510 | G9: S | H9: 2510S | I9: LCH04 | J9: THLCH | K9: IDJKT | L9: N | M9: N | N9: N | P9: 46025.333 | Q9: 46025.375 | R9: 46026 | S9: =ROUND((Q9-P9)*24,4) -> 1 | T9: =TEXT(P9,"YYYY-MM") -> 2026-01 | U9: =RANK(S9,$S$2:$S$670)+COUNTIF($S$2:S9,S9)-1 -> 372 | V9: =ROUND((R9-Q9)*24,4) -> 15 | W9: =ROUND((R9-P9)*24,4) -> 16 | X9: =TEXT(P9,"dddd") -> Saturday | Y9: =HOUR(Q9) -> 9
A10: VTS | B10: SKOR | C10: SKY ORION | D10: CKL | E10: 05 | F10: 2515 | G10: S | H10: 2515S | I10: LCH04 | J10: THLCH | K10: THBKK | L10: N | M10: N | N10: N | P10: 46026.292 | Q10: 46026.333 | R10: 46026.667 | S10: =ROUND((Q10-P10)*24,4) -> 1 | T10: =TEXT(P10,"YYYY-MM") -> 2026-01 | U10: =RANK(S10,$S$2:$S$670)+COUNTIF($S$2:S10,S10)-1 -> 373 | V10: =ROUND((R10-Q10)*24,4) -> 8 | W10: =ROUND((R10-P10)*24,4) -> 9 | X10: =TEXT(P10,"dddd") -> Sunday | Y10: =HOUR(Q10) -> 8
A11: NTX | B11: PGPO | C11: PEGASUS PROTO | D11: NAM | E11: 08 | F11: 2514 | G11: N | H11: 2514N | I11: LCH04 | J11: THLCH | K11: VNSGN | L11: N | M11: N | N11: N | P11: 46026.375 | Q11: 46026.417 | R11: 46026.75 | S11: =ROUND((Q11-P11)*24,4) -> 1 | T11: =TEXT(P11,"YYYY-MM") -> 2026-01 | U11: =RANK(S11,$S$2:$S$670)+COUNTIF($S$2:S11,S11)-1 -> 374 | V11: =ROUND((R11-Q11)*24,4) -> 8 | W11: =ROUND((R11-P11)*24,4) -> 9 | X11: =TEXT(P11,"dddd") -> Sunday | Y11: =HOUR(Q11) -> 10
A12: KTS1 | B12: KMGY | C12: KMTC GWANGYANG | D12: KMT | E12: 07 | F12: 2513 | G12: N | H12: 2513N | I12: LCH04 | J12: THLCH | K12: HKHKG | L12: N | M12: N | N12: N | P12: 46026.683 | Q12: 46026.708 | R12: 46027.021 | S12: =ROUND((Q12-P12)*24,4) -> 0.6 | T12: =TEXT(P12,"YYYY-MM") -> 2026-01 | U12: =RANK(S12,$S$2:$S$670)+COUNTIF($S$2:S12,S12)-1 -> 596 | V12: =ROUND((R12-Q12)*24,4) -> 7.5 | W12: =ROUND((R12-P12)*24,4) -> 8.1 | X12: =TEXT(P12,"dddd") -> Sunday | Y12: =HOUR(Q12) -> 17
A13: VTS | B13: SKOR | C13: SKY ORION | D13: CKL | E13: 06 | F13: 2515 | G13: N | H13: 2515N | I13: BKK01 | J13: THBKK | K13: THLCH | L13: N | M13: N | N13: N | P13: 46026.771 | Q13: 46027.75 | R13: 46028.625 | S13: =ROUND((Q13-P13)*24,4) -> 23.5 | T13: =TEXT(P13,"YYYY-MM") -> 2026-01 | U13: =RANK(S13,$S$2:$S$670)+COUNTIF($S$2:S13,S13)-1 -> 36 | V13: =ROUND((R13-Q13)*24,4) -> 21 | W13: =ROUND((R13-P13)*24,4) -> 44.5 | X13: =TEXT(P13,"dddd") -> Sunday | Y13: =HOUR(Q13) -> 18
... A28: KTS1 | B28: SWMM | C28: SAWASDEE MIMOSA | D28: SKR | E28: 06 | F28: 2537 | G28: N | H28: 2537N | I28: BKK01 | J28: THBKK | K28: THLCH | L28: N | M28: N | N28: N | P28: 46032.708 | Q28: 46033.5 | R28: 46035.208 | S28: =ROUND((Q28-P28)*24,4) -> 19 | T28: =TEXT(P28,"YYYY-MM") -> 2026-01 | U28: =RANK(S28,$S$2:$S$670)+COUNTIF($S$2:S28,S28)-1 -> 53 | V28: =ROUND((R28-Q28)*24,4) -> 41 | W28: =ROUND((R28-P28)*24,4) -> 60 | X28: =TEXT(P28,"dddd") -> Saturday | Y28: =HOUR(Q28) -> 12
A29: KST | B29: SKSH | C29: SKY SUNSHINE | D29: CKL | E29: 04 | F29: 2517 | G29: S | H29: 2517S | I29: LCH05 | J29: THLCH | K29: THBKK | L29: Y | M29: N | N29: N | O29: BUY(CKL) | P29: 46033.647 | Q29: 46033.647 | R29: 46033.648 | S29: =ROUND((Q29-P29)*24,4) -> 0.0167 | T29: =TEXT(P29,"YYYY-MM") -> 2026-01 | U29: =RANK(S29,$S$2:$S$670)+COUNTIF($S$2:S29,S29)-1 -> 624 | V29: =ROUND((R29-Q29)*24,4) -> 0.0167 | W29: =ROUND((R29-P29)*24,4) -> 0.0333 | X29: =TEXT(P29,"dddd") -> Sunday | Y29: =HOUR(Q29) -> 15
A30: KST | B30: SKSH | C30: SKY SUNSHINE | D30: CKL | E30: 05 | F30: 2517 | G30: N | H30: 2517N | I30: BKK02 | J30: THBKK | K30: THLCH | L30: Y | M30: N | N30: N | O30: BUY(CKL) | P30: 46033.649 | Q30: 46033.649 | R30: 46033.65 | S30: =ROUND((Q30-P30)*24,4) -> 0.0167 | T30: =TEXT(P30,"YYYY-MM") -> 2026-01 | U30: =RANK(S30,$S$2:$S$670)+COUNTIF($S$2:S30,S30)-1 -> 625 | V30: =ROUND((R30-Q30)*24,4) -> 0.0167 | W30: =ROUND((R30-P30)*24,4) -> 0.0333 | X30: =TEXT(P30,"dddd") -> Sunday | Y30: =HOUR(Q30) -> 15
A31: BTS | B31: SWAT | C31: SAWASDEE ATLANTIC | D31: SKR | E31: 06 | F31: 2526 | G31: S | H31: 2526S | I31: LCH01 | J31: THLCH | K31: THBKK | L31: N | M31: N | N31: N | P31: 46033.771 | Q31: 46033.812 | R31: 46034.292 | S31: =ROUND((Q31-P31)*24,4) -> 1 | T31: =TEXT(P31,"YYYY-MM") -> 2026-01 | U31: =RANK(S31,$S$2:$S$670)+COUNTIF($S$2:S31,S31)-1 -> 380 | V31: =ROUND((R31-Q31)*24,4) -> 11.5 | W31: =ROUND((R31-P31)*24,4) -> 12.5 | X31: =TEXT(P31,"dddd") -> Sunday | Y31: =HOUR(Q31) -> 19
